[2025-08-11T09:32:23.206+0000] {processor.py:161} INFO - Started process (PID=45) to work on /opt/airflow/dags/twitter_love_dag.py
[2025-08-11T09:32:23.208+0000] {processor.py:830} INFO - Processing file /opt/airflow/dags/twitter_love_dag.py for tasks to queue
[2025-08-11T09:32:23.210+0000] {logging_mixin.py:188} INFO - [2025-08-11T09:32:23.209+0000] {dagbag.py:540} INFO - Filling up the DagBag from /opt/airflow/dags/twitter_love_dag.py
[2025-08-11T09:32:24.893+0000] {logging_mixin.py:188} INFO - [2025-08-11T09:32:24.872+0000] {dagbag.py:350} ERROR - Failed to import: /opt/airflow/dags/twitter_love_dag.py
Traceback (most recent call last):
  File "/home/airflow/.local/lib/python3.10/site-packages/airflow/models/dagbag.py", line 346, in parse
    loader.exec_module(new_module)
  File "<frozen importlib._bootstrap_external>", line 883, in exec_module
  File "<frozen importlib._bootstrap>", line 241, in _call_with_frames_removed
  File "/opt/airflow/dags/twitter_love_dag.py", line 15, in <module>
    with open(CREDENTIALS_PATH) as f:
FileNotFoundError: [Errno 2] No such file or directory: '/opt/airflow/data/twitter_api.json'
[2025-08-11T09:32:24.897+0000] {processor.py:842} WARNING - No viable dags retrieved from /opt/airflow/dags/twitter_love_dag.py
[2025-08-11T09:32:25.115+0000] {processor.py:183} INFO - Processing /opt/airflow/dags/twitter_love_dag.py took 1.915 seconds
[2025-08-11T09:32:56.144+0000] {processor.py:161} INFO - Started process (PID=49) to work on /opt/airflow/dags/twitter_love_dag.py
[2025-08-11T09:32:56.146+0000] {processor.py:830} INFO - Processing file /opt/airflow/dags/twitter_love_dag.py for tasks to queue
[2025-08-11T09:32:56.149+0000] {logging_mixin.py:188} INFO - [2025-08-11T09:32:56.148+0000] {dagbag.py:540} INFO - Filling up the DagBag from /opt/airflow/dags/twitter_love_dag.py
[2025-08-11T09:32:59.737+0000] {logging_mixin.py:188} INFO - [2025-08-11T09:32:59.732+0000] {dagbag.py:350} ERROR - Failed to import: /opt/airflow/dags/twitter_love_dag.py
Traceback (most recent call last):
  File "/home/airflow/.local/lib/python3.10/site-packages/airflow/models/dagbag.py", line 346, in parse
    loader.exec_module(new_module)
  File "<frozen importlib._bootstrap_external>", line 883, in exec_module
  File "<frozen importlib._bootstrap>", line 241, in _call_with_frames_removed
  File "/opt/airflow/dags/twitter_love_dag.py", line 15, in <module>
    with open(CREDENTIALS_PATH) as f:
FileNotFoundError: [Errno 2] No such file or directory: '/opt/airflow/data/twitter_api.json'
[2025-08-11T09:32:59.739+0000] {processor.py:842} WARNING - No viable dags retrieved from /opt/airflow/dags/twitter_love_dag.py
[2025-08-11T09:32:59.766+0000] {processor.py:183} INFO - Processing /opt/airflow/dags/twitter_love_dag.py took 2.718 seconds
[2025-08-11T09:33:30.366+0000] {processor.py:161} INFO - Started process (PID=55) to work on /opt/airflow/dags/twitter_love_dag.py
[2025-08-11T09:33:30.368+0000] {processor.py:830} INFO - Processing file /opt/airflow/dags/twitter_love_dag.py for tasks to queue
[2025-08-11T09:33:30.371+0000] {logging_mixin.py:188} INFO - [2025-08-11T09:33:30.370+0000] {dagbag.py:540} INFO - Filling up the DagBag from /opt/airflow/dags/twitter_love_dag.py
[2025-08-11T09:33:31.218+0000] {logging_mixin.py:188} INFO - [2025-08-11T09:33:31.171+0000] {dagbag.py:350} ERROR - Failed to import: /opt/airflow/dags/twitter_love_dag.py
Traceback (most recent call last):
  File "/home/airflow/.local/lib/python3.10/site-packages/airflow/models/dagbag.py", line 346, in parse
    loader.exec_module(new_module)
  File "<frozen importlib._bootstrap_external>", line 883, in exec_module
  File "<frozen importlib._bootstrap>", line 241, in _call_with_frames_removed
  File "/opt/airflow/dags/twitter_love_dag.py", line 15, in <module>
    with open(CREDENTIALS_PATH) as f:
FileNotFoundError: [Errno 2] No such file or directory: '/opt/airflow/data/twitter_api.json'
[2025-08-11T09:33:31.223+0000] {processor.py:842} WARNING - No viable dags retrieved from /opt/airflow/dags/twitter_love_dag.py
[2025-08-11T09:33:31.275+0000] {processor.py:183} INFO - Processing /opt/airflow/dags/twitter_love_dag.py took 0.922 seconds
[2025-08-11T09:34:02.334+0000] {processor.py:161} INFO - Started process (PID=61) to work on /opt/airflow/dags/twitter_love_dag.py
[2025-08-11T09:34:02.335+0000] {processor.py:830} INFO - Processing file /opt/airflow/dags/twitter_love_dag.py for tasks to queue
[2025-08-11T09:34:02.337+0000] {logging_mixin.py:188} INFO - [2025-08-11T09:34:02.337+0000] {dagbag.py:540} INFO - Filling up the DagBag from /opt/airflow/dags/twitter_love_dag.py
[2025-08-11T09:34:02.950+0000] {logging_mixin.py:188} INFO - [2025-08-11T09:34:02.943+0000] {dagbag.py:350} ERROR - Failed to import: /opt/airflow/dags/twitter_love_dag.py
Traceback (most recent call last):
  File "/home/airflow/.local/lib/python3.10/site-packages/airflow/models/dagbag.py", line 346, in parse
    loader.exec_module(new_module)
  File "<frozen importlib._bootstrap_external>", line 883, in exec_module
  File "<frozen importlib._bootstrap>", line 241, in _call_with_frames_removed
  File "/opt/airflow/dags/twitter_love_dag.py", line 15, in <module>
    with open(CREDENTIALS_PATH) as f:
FileNotFoundError: [Errno 2] No such file or directory: '/opt/airflow/data/twitter_api.json'
[2025-08-11T09:34:02.952+0000] {processor.py:842} WARNING - No viable dags retrieved from /opt/airflow/dags/twitter_love_dag.py
[2025-08-11T09:34:02.971+0000] {processor.py:183} INFO - Processing /opt/airflow/dags/twitter_love_dag.py took 0.642 seconds
[2025-08-11T09:34:33.268+0000] {processor.py:161} INFO - Started process (PID=67) to work on /opt/airflow/dags/twitter_love_dag.py
[2025-08-11T09:34:33.270+0000] {processor.py:830} INFO - Processing file /opt/airflow/dags/twitter_love_dag.py for tasks to queue
[2025-08-11T09:34:33.272+0000] {logging_mixin.py:188} INFO - [2025-08-11T09:34:33.271+0000] {dagbag.py:540} INFO - Filling up the DagBag from /opt/airflow/dags/twitter_love_dag.py
[2025-08-11T09:34:33.970+0000] {logging_mixin.py:188} INFO - [2025-08-11T09:34:33.964+0000] {dagbag.py:350} ERROR - Failed to import: /opt/airflow/dags/twitter_love_dag.py
Traceback (most recent call last):
  File "/home/airflow/.local/lib/python3.10/site-packages/airflow/models/dagbag.py", line 346, in parse
    loader.exec_module(new_module)
  File "<frozen importlib._bootstrap_external>", line 883, in exec_module
  File "<frozen importlib._bootstrap>", line 241, in _call_with_frames_removed
  File "/opt/airflow/dags/twitter_love_dag.py", line 15, in <module>
    with open(CREDENTIALS_PATH) as f:
FileNotFoundError: [Errno 2] No such file or directory: '/opt/airflow/data/twitter_api.json'
[2025-08-11T09:34:33.972+0000] {processor.py:842} WARNING - No viable dags retrieved from /opt/airflow/dags/twitter_love_dag.py
[2025-08-11T09:34:34.005+0000] {processor.py:183} INFO - Processing /opt/airflow/dags/twitter_love_dag.py took 0.742 seconds
[2025-08-11T09:35:04.613+0000] {processor.py:161} INFO - Started process (PID=73) to work on /opt/airflow/dags/twitter_love_dag.py
[2025-08-11T09:35:04.614+0000] {processor.py:830} INFO - Processing file /opt/airflow/dags/twitter_love_dag.py for tasks to queue
[2025-08-11T09:35:04.616+0000] {logging_mixin.py:188} INFO - [2025-08-11T09:35:04.616+0000] {dagbag.py:540} INFO - Filling up the DagBag from /opt/airflow/dags/twitter_love_dag.py
[2025-08-11T09:35:05.212+0000] {logging_mixin.py:188} INFO - [2025-08-11T09:35:05.206+0000] {dagbag.py:350} ERROR - Failed to import: /opt/airflow/dags/twitter_love_dag.py
Traceback (most recent call last):
  File "/home/airflow/.local/lib/python3.10/site-packages/airflow/models/dagbag.py", line 346, in parse
    loader.exec_module(new_module)
  File "<frozen importlib._bootstrap_external>", line 883, in exec_module
  File "<frozen importlib._bootstrap>", line 241, in _call_with_frames_removed
  File "/opt/airflow/dags/twitter_love_dag.py", line 15, in <module>
    with open(CREDENTIALS_PATH) as f:
FileNotFoundError: [Errno 2] No such file or directory: '/opt/airflow/data/twitter_api.json'
[2025-08-11T09:35:05.215+0000] {processor.py:842} WARNING - No viable dags retrieved from /opt/airflow/dags/twitter_love_dag.py
[2025-08-11T09:35:05.240+0000] {processor.py:183} INFO - Processing /opt/airflow/dags/twitter_love_dag.py took 0.634 seconds
[2025-08-11T09:35:35.531+0000] {processor.py:161} INFO - Started process (PID=79) to work on /opt/airflow/dags/twitter_love_dag.py
[2025-08-11T09:35:35.533+0000] {processor.py:830} INFO - Processing file /opt/airflow/dags/twitter_love_dag.py for tasks to queue
[2025-08-11T09:35:35.537+0000] {logging_mixin.py:188} INFO - [2025-08-11T09:35:35.537+0000] {dagbag.py:540} INFO - Filling up the DagBag from /opt/airflow/dags/twitter_love_dag.py
[2025-08-11T09:35:36.053+0000] {logging_mixin.py:188} INFO - [2025-08-11T09:35:36.045+0000] {dagbag.py:350} ERROR - Failed to import: /opt/airflow/dags/twitter_love_dag.py
Traceback (most recent call last):
  File "/home/airflow/.local/lib/python3.10/site-packages/airflow/models/dagbag.py", line 346, in parse
    loader.exec_module(new_module)
  File "<frozen importlib._bootstrap_external>", line 883, in exec_module
  File "<frozen importlib._bootstrap>", line 241, in _call_with_frames_removed
  File "/opt/airflow/dags/twitter_love_dag.py", line 15, in <module>
    with open(CREDENTIALS_PATH) as f:
FileNotFoundError: [Errno 2] No such file or directory: '/opt/airflow/data/twitter_api.json'
[2025-08-11T09:35:36.059+0000] {processor.py:842} WARNING - No viable dags retrieved from /opt/airflow/dags/twitter_love_dag.py
[2025-08-11T09:35:36.107+0000] {processor.py:183} INFO - Processing /opt/airflow/dags/twitter_love_dag.py took 0.588 seconds
[2025-08-11T09:36:06.304+0000] {processor.py:161} INFO - Started process (PID=85) to work on /opt/airflow/dags/twitter_love_dag.py
[2025-08-11T09:36:06.308+0000] {processor.py:830} INFO - Processing file /opt/airflow/dags/twitter_love_dag.py for tasks to queue
[2025-08-11T09:36:06.311+0000] {logging_mixin.py:188} INFO - [2025-08-11T09:36:06.310+0000] {dagbag.py:540} INFO - Filling up the DagBag from /opt/airflow/dags/twitter_love_dag.py
[2025-08-11T09:36:06.812+0000] {logging_mixin.py:188} INFO - [2025-08-11T09:36:06.808+0000] {dagbag.py:350} ERROR - Failed to import: /opt/airflow/dags/twitter_love_dag.py
Traceback (most recent call last):
  File "/home/airflow/.local/lib/python3.10/site-packages/airflow/models/dagbag.py", line 346, in parse
    loader.exec_module(new_module)
  File "<frozen importlib._bootstrap_external>", line 883, in exec_module
  File "<frozen importlib._bootstrap>", line 241, in _call_with_frames_removed
  File "/opt/airflow/dags/twitter_love_dag.py", line 15, in <module>
    with open(CREDENTIALS_PATH) as f:
FileNotFoundError: [Errno 2] No such file or directory: '/opt/airflow/data/twitter_api.json'
[2025-08-11T09:36:06.814+0000] {processor.py:842} WARNING - No viable dags retrieved from /opt/airflow/dags/twitter_love_dag.py
[2025-08-11T09:36:06.832+0000] {processor.py:183} INFO - Processing /opt/airflow/dags/twitter_love_dag.py took 0.534 seconds
[2025-08-11T09:36:38.048+0000] {processor.py:161} INFO - Started process (PID=91) to work on /opt/airflow/dags/twitter_love_dag.py
[2025-08-11T09:36:38.050+0000] {processor.py:830} INFO - Processing file /opt/airflow/dags/twitter_love_dag.py for tasks to queue
[2025-08-11T09:36:38.054+0000] {logging_mixin.py:188} INFO - [2025-08-11T09:36:38.053+0000] {dagbag.py:540} INFO - Filling up the DagBag from /opt/airflow/dags/twitter_love_dag.py
[2025-08-11T09:36:39.086+0000] {logging_mixin.py:188} INFO - [2025-08-11T09:36:38.785+0000] {dagbag.py:350} ERROR - Failed to import: /opt/airflow/dags/twitter_love_dag.py
Traceback (most recent call last):
  File "/home/airflow/.local/lib/python3.10/site-packages/airflow/models/dagbag.py", line 346, in parse
    loader.exec_module(new_module)
  File "<frozen importlib._bootstrap_external>", line 883, in exec_module
  File "<frozen importlib._bootstrap>", line 241, in _call_with_frames_removed
  File "/opt/airflow/dags/twitter_love_dag.py", line 15, in <module>
    with open(CREDENTIALS_PATH) as f:
FileNotFoundError: [Errno 2] No such file or directory: '/opt/airflow/data/twitter_api.json'
[2025-08-11T09:36:39.088+0000] {processor.py:842} WARNING - No viable dags retrieved from /opt/airflow/dags/twitter_love_dag.py
[2025-08-11T09:36:39.111+0000] {processor.py:183} INFO - Processing /opt/airflow/dags/twitter_love_dag.py took 1.075 seconds
[2025-08-11T09:37:09.310+0000] {processor.py:161} INFO - Started process (PID=97) to work on /opt/airflow/dags/twitter_love_dag.py
[2025-08-11T09:37:09.312+0000] {processor.py:830} INFO - Processing file /opt/airflow/dags/twitter_love_dag.py for tasks to queue
[2025-08-11T09:37:09.314+0000] {logging_mixin.py:188} INFO - [2025-08-11T09:37:09.314+0000] {dagbag.py:540} INFO - Filling up the DagBag from /opt/airflow/dags/twitter_love_dag.py
[2025-08-11T09:37:09.798+0000] {logging_mixin.py:188} INFO - [2025-08-11T09:37:09.772+0000] {dagbag.py:350} ERROR - Failed to import: /opt/airflow/dags/twitter_love_dag.py
Traceback (most recent call last):
  File "/home/airflow/.local/lib/python3.10/site-packages/airflow/models/dagbag.py", line 346, in parse
    loader.exec_module(new_module)
  File "<frozen importlib._bootstrap_external>", line 883, in exec_module
  File "<frozen importlib._bootstrap>", line 241, in _call_with_frames_removed
  File "/opt/airflow/dags/twitter_love_dag.py", line 15, in <module>
    with open(CREDENTIALS_PATH) as f:
FileNotFoundError: [Errno 2] No such file or directory: '/opt/airflow/data/twitter_api.json'
[2025-08-11T09:37:09.805+0000] {processor.py:842} WARNING - No viable dags retrieved from /opt/airflow/dags/twitter_love_dag.py
[2025-08-11T09:37:09.844+0000] {processor.py:183} INFO - Processing /opt/airflow/dags/twitter_love_dag.py took 0.540 seconds
[2025-08-11T09:37:40.288+0000] {processor.py:161} INFO - Started process (PID=103) to work on /opt/airflow/dags/twitter_love_dag.py
[2025-08-11T09:37:40.291+0000] {processor.py:830} INFO - Processing file /opt/airflow/dags/twitter_love_dag.py for tasks to queue
[2025-08-11T09:37:40.293+0000] {logging_mixin.py:188} INFO - [2025-08-11T09:37:40.293+0000] {dagbag.py:540} INFO - Filling up the DagBag from /opt/airflow/dags/twitter_love_dag.py
[2025-08-11T09:37:40.847+0000] {logging_mixin.py:188} INFO - [2025-08-11T09:37:40.831+0000] {dagbag.py:350} ERROR - Failed to import: /opt/airflow/dags/twitter_love_dag.py
Traceback (most recent call last):
  File "/home/airflow/.local/lib/python3.10/site-packages/airflow/models/dagbag.py", line 346, in parse
    loader.exec_module(new_module)
  File "<frozen importlib._bootstrap_external>", line 883, in exec_module
  File "<frozen importlib._bootstrap>", line 241, in _call_with_frames_removed
  File "/opt/airflow/dags/twitter_love_dag.py", line 15, in <module>
    with open(CREDENTIALS_PATH) as f:
FileNotFoundError: [Errno 2] No such file or directory: '/opt/airflow/data/twitter_api.json'
[2025-08-11T09:37:40.849+0000] {processor.py:842} WARNING - No viable dags retrieved from /opt/airflow/dags/twitter_love_dag.py
[2025-08-11T09:37:40.867+0000] {processor.py:183} INFO - Processing /opt/airflow/dags/twitter_love_dag.py took 0.587 seconds
[2025-08-11T09:38:10.949+0000] {processor.py:161} INFO - Started process (PID=109) to work on /opt/airflow/dags/twitter_love_dag.py
[2025-08-11T09:38:10.952+0000] {processor.py:830} INFO - Processing file /opt/airflow/dags/twitter_love_dag.py for tasks to queue
[2025-08-11T09:38:10.954+0000] {logging_mixin.py:188} INFO - [2025-08-11T09:38:10.954+0000] {dagbag.py:540} INFO - Filling up the DagBag from /opt/airflow/dags/twitter_love_dag.py
[2025-08-11T09:38:12.017+0000] {logging_mixin.py:188} INFO - [2025-08-11T09:38:12.009+0000] {dagbag.py:350} ERROR - Failed to import: /opt/airflow/dags/twitter_love_dag.py
Traceback (most recent call last):
  File "/home/airflow/.local/lib/python3.10/site-packages/airflow/models/dagbag.py", line 346, in parse
    loader.exec_module(new_module)
  File "<frozen importlib._bootstrap_external>", line 883, in exec_module
  File "<frozen importlib._bootstrap>", line 241, in _call_with_frames_removed
  File "/opt/airflow/dags/twitter_love_dag.py", line 15, in <module>
    with open(CREDENTIALS_PATH) as f:
FileNotFoundError: [Errno 2] No such file or directory: '/opt/airflow/data/twitter_api.json'
[2025-08-11T09:38:12.020+0000] {processor.py:842} WARNING - No viable dags retrieved from /opt/airflow/dags/twitter_love_dag.py
[2025-08-11T09:38:12.070+0000] {processor.py:183} INFO - Processing /opt/airflow/dags/twitter_love_dag.py took 1.135 seconds
[2025-08-11T09:38:42.213+0000] {processor.py:161} INFO - Started process (PID=115) to work on /opt/airflow/dags/twitter_love_dag.py
[2025-08-11T09:38:42.216+0000] {processor.py:830} INFO - Processing file /opt/airflow/dags/twitter_love_dag.py for tasks to queue
[2025-08-11T09:38:42.220+0000] {logging_mixin.py:188} INFO - [2025-08-11T09:38:42.219+0000] {dagbag.py:540} INFO - Filling up the DagBag from /opt/airflow/dags/twitter_love_dag.py
[2025-08-11T09:38:42.782+0000] {logging_mixin.py:188} INFO - [2025-08-11T09:38:42.765+0000] {dagbag.py:350} ERROR - Failed to import: /opt/airflow/dags/twitter_love_dag.py
Traceback (most recent call last):
  File "/home/airflow/.local/lib/python3.10/site-packages/airflow/models/dagbag.py", line 346, in parse
    loader.exec_module(new_module)
  File "<frozen importlib._bootstrap_external>", line 883, in exec_module
  File "<frozen importlib._bootstrap>", line 241, in _call_with_frames_removed
  File "/opt/airflow/dags/twitter_love_dag.py", line 15, in <module>
    with open(CREDENTIALS_PATH) as f:
FileNotFoundError: [Errno 2] No such file or directory: '/opt/airflow/data/twitter_api.json'
[2025-08-11T09:38:42.783+0000] {processor.py:842} WARNING - No viable dags retrieved from /opt/airflow/dags/twitter_love_dag.py
[2025-08-11T09:38:42.808+0000] {processor.py:183} INFO - Processing /opt/airflow/dags/twitter_love_dag.py took 0.605 seconds
[2025-08-11T09:39:13.131+0000] {processor.py:161} INFO - Started process (PID=121) to work on /opt/airflow/dags/twitter_love_dag.py
[2025-08-11T09:39:13.132+0000] {processor.py:830} INFO - Processing file /opt/airflow/dags/twitter_love_dag.py for tasks to queue
[2025-08-11T09:39:13.135+0000] {logging_mixin.py:188} INFO - [2025-08-11T09:39:13.135+0000] {dagbag.py:540} INFO - Filling up the DagBag from /opt/airflow/dags/twitter_love_dag.py
[2025-08-11T09:39:13.661+0000] {logging_mixin.py:188} INFO - [2025-08-11T09:39:13.657+0000] {dagbag.py:350} ERROR - Failed to import: /opt/airflow/dags/twitter_love_dag.py
Traceback (most recent call last):
  File "/home/airflow/.local/lib/python3.10/site-packages/airflow/models/dagbag.py", line 346, in parse
    loader.exec_module(new_module)
  File "<frozen importlib._bootstrap_external>", line 883, in exec_module
  File "<frozen importlib._bootstrap>", line 241, in _call_with_frames_removed
  File "/opt/airflow/dags/twitter_love_dag.py", line 15, in <module>
    with open(CREDENTIALS_PATH) as f:
FileNotFoundError: [Errno 2] No such file or directory: '/opt/airflow/data/twitter_api.json'
[2025-08-11T09:39:13.662+0000] {processor.py:842} WARNING - No viable dags retrieved from /opt/airflow/dags/twitter_love_dag.py
[2025-08-11T09:39:13.685+0000] {processor.py:183} INFO - Processing /opt/airflow/dags/twitter_love_dag.py took 0.561 seconds
[2025-08-11T09:39:44.442+0000] {processor.py:161} INFO - Started process (PID=127) to work on /opt/airflow/dags/twitter_love_dag.py
[2025-08-11T09:39:44.444+0000] {processor.py:830} INFO - Processing file /opt/airflow/dags/twitter_love_dag.py for tasks to queue
[2025-08-11T09:39:44.447+0000] {logging_mixin.py:188} INFO - [2025-08-11T09:39:44.446+0000] {dagbag.py:540} INFO - Filling up the DagBag from /opt/airflow/dags/twitter_love_dag.py
[2025-08-11T09:39:45.788+0000] {logging_mixin.py:188} INFO - [2025-08-11T09:39:45.780+0000] {dagbag.py:350} ERROR - Failed to import: /opt/airflow/dags/twitter_love_dag.py
Traceback (most recent call last):
  File "/home/airflow/.local/lib/python3.10/site-packages/airflow/models/dagbag.py", line 346, in parse
    loader.exec_module(new_module)
  File "<frozen importlib._bootstrap_external>", line 883, in exec_module
  File "<frozen importlib._bootstrap>", line 241, in _call_with_frames_removed
  File "/opt/airflow/dags/twitter_love_dag.py", line 15, in <module>
    with open(CREDENTIALS_PATH) as f:
FileNotFoundError: [Errno 2] No such file or directory: '/opt/airflow/data/twitter_api.json'
[2025-08-11T09:39:45.790+0000] {processor.py:842} WARNING - No viable dags retrieved from /opt/airflow/dags/twitter_love_dag.py
[2025-08-11T09:39:45.859+0000] {processor.py:183} INFO - Processing /opt/airflow/dags/twitter_love_dag.py took 1.425 seconds
[2025-08-11T09:40:16.567+0000] {processor.py:161} INFO - Started process (PID=133) to work on /opt/airflow/dags/twitter_love_dag.py
[2025-08-11T09:40:16.570+0000] {processor.py:830} INFO - Processing file /opt/airflow/dags/twitter_love_dag.py for tasks to queue
[2025-08-11T09:40:16.572+0000] {logging_mixin.py:188} INFO - [2025-08-11T09:40:16.572+0000] {dagbag.py:540} INFO - Filling up the DagBag from /opt/airflow/dags/twitter_love_dag.py
[2025-08-11T09:40:17.177+0000] {logging_mixin.py:188} INFO - [2025-08-11T09:40:17.170+0000] {dagbag.py:350} ERROR - Failed to import: /opt/airflow/dags/twitter_love_dag.py
Traceback (most recent call last):
  File "/home/airflow/.local/lib/python3.10/site-packages/airflow/models/dagbag.py", line 346, in parse
    loader.exec_module(new_module)
  File "<frozen importlib._bootstrap_external>", line 883, in exec_module
  File "<frozen importlib._bootstrap>", line 241, in _call_with_frames_removed
  File "/opt/airflow/dags/twitter_love_dag.py", line 15, in <module>
    with open(CREDENTIALS_PATH) as f:
FileNotFoundError: [Errno 2] No such file or directory: '/opt/airflow/data/twitter_api.json'
[2025-08-11T09:40:17.179+0000] {processor.py:842} WARNING - No viable dags retrieved from /opt/airflow/dags/twitter_love_dag.py
[2025-08-11T09:40:17.198+0000] {processor.py:183} INFO - Processing /opt/airflow/dags/twitter_love_dag.py took 0.644 seconds
[2025-08-11T09:40:48.369+0000] {processor.py:161} INFO - Started process (PID=139) to work on /opt/airflow/dags/twitter_love_dag.py
[2025-08-11T09:40:48.376+0000] {processor.py:830} INFO - Processing file /opt/airflow/dags/twitter_love_dag.py for tasks to queue
[2025-08-11T09:40:48.381+0000] {logging_mixin.py:188} INFO - [2025-08-11T09:40:48.380+0000] {dagbag.py:540} INFO - Filling up the DagBag from /opt/airflow/dags/twitter_love_dag.py
[2025-08-11T09:40:49.068+0000] {logging_mixin.py:188} INFO - [2025-08-11T09:40:49.057+0000] {dagbag.py:350} ERROR - Failed to import: /opt/airflow/dags/twitter_love_dag.py
Traceback (most recent call last):
  File "/home/airflow/.local/lib/python3.10/site-packages/airflow/models/dagbag.py", line 346, in parse
    loader.exec_module(new_module)
  File "<frozen importlib._bootstrap_external>", line 883, in exec_module
  File "<frozen importlib._bootstrap>", line 241, in _call_with_frames_removed
  File "/opt/airflow/dags/twitter_love_dag.py", line 15, in <module>
    with open(CREDENTIALS_PATH) as f:
FileNotFoundError: [Errno 2] No such file or directory: '/opt/airflow/data/twitter_api.json'
[2025-08-11T09:40:49.074+0000] {processor.py:842} WARNING - No viable dags retrieved from /opt/airflow/dags/twitter_love_dag.py
[2025-08-11T09:40:49.113+0000] {processor.py:183} INFO - Processing /opt/airflow/dags/twitter_love_dag.py took 0.774 seconds
[2025-08-11T09:41:20.069+0000] {processor.py:161} INFO - Started process (PID=145) to work on /opt/airflow/dags/twitter_love_dag.py
[2025-08-11T09:41:20.071+0000] {processor.py:830} INFO - Processing file /opt/airflow/dags/twitter_love_dag.py for tasks to queue
[2025-08-11T09:41:20.073+0000] {logging_mixin.py:188} INFO - [2025-08-11T09:41:20.072+0000] {dagbag.py:540} INFO - Filling up the DagBag from /opt/airflow/dags/twitter_love_dag.py
[2025-08-11T09:41:20.577+0000] {logging_mixin.py:188} INFO - [2025-08-11T09:41:20.573+0000] {dagbag.py:350} ERROR - Failed to import: /opt/airflow/dags/twitter_love_dag.py
Traceback (most recent call last):
  File "/home/airflow/.local/lib/python3.10/site-packages/airflow/models/dagbag.py", line 346, in parse
    loader.exec_module(new_module)
  File "<frozen importlib._bootstrap_external>", line 883, in exec_module
  File "<frozen importlib._bootstrap>", line 241, in _call_with_frames_removed
  File "/opt/airflow/dags/twitter_love_dag.py", line 15, in <module>
    with open(CREDENTIALS_PATH) as f:
FileNotFoundError: [Errno 2] No such file or directory: '/opt/airflow/data/twitter_api.json'
[2025-08-11T09:41:20.578+0000] {processor.py:842} WARNING - No viable dags retrieved from /opt/airflow/dags/twitter_love_dag.py
[2025-08-11T09:41:20.595+0000] {processor.py:183} INFO - Processing /opt/airflow/dags/twitter_love_dag.py took 0.531 seconds
[2025-08-11T09:41:50.839+0000] {processor.py:161} INFO - Started process (PID=151) to work on /opt/airflow/dags/twitter_love_dag.py
[2025-08-11T09:41:50.887+0000] {processor.py:830} INFO - Processing file /opt/airflow/dags/twitter_love_dag.py for tasks to queue
[2025-08-11T09:41:50.891+0000] {logging_mixin.py:188} INFO - [2025-08-11T09:41:50.891+0000] {dagbag.py:540} INFO - Filling up the DagBag from /opt/airflow/dags/twitter_love_dag.py
[2025-08-11T09:41:51.381+0000] {logging_mixin.py:188} INFO - [2025-08-11T09:41:51.373+0000] {dagbag.py:350} ERROR - Failed to import: /opt/airflow/dags/twitter_love_dag.py
Traceback (most recent call last):
  File "/home/airflow/.local/lib/python3.10/site-packages/airflow/models/dagbag.py", line 346, in parse
    loader.exec_module(new_module)
  File "<frozen importlib._bootstrap_external>", line 883, in exec_module
  File "<frozen importlib._bootstrap>", line 241, in _call_with_frames_removed
  File "/opt/airflow/dags/twitter_love_dag.py", line 15, in <module>
    with open(CREDENTIALS_PATH) as f:
FileNotFoundError: [Errno 2] No such file or directory: '/opt/airflow/data/twitter_api.json'
[2025-08-11T09:41:51.393+0000] {processor.py:842} WARNING - No viable dags retrieved from /opt/airflow/dags/twitter_love_dag.py
[2025-08-11T09:41:51.414+0000] {processor.py:183} INFO - Processing /opt/airflow/dags/twitter_love_dag.py took 0.582 seconds
[2025-08-11T09:42:21.512+0000] {processor.py:161} INFO - Started process (PID=157) to work on /opt/airflow/dags/twitter_love_dag.py
[2025-08-11T09:42:21.518+0000] {processor.py:830} INFO - Processing file /opt/airflow/dags/twitter_love_dag.py for tasks to queue
[2025-08-11T09:42:21.526+0000] {logging_mixin.py:188} INFO - [2025-08-11T09:42:21.525+0000] {dagbag.py:540} INFO - Filling up the DagBag from /opt/airflow/dags/twitter_love_dag.py
[2025-08-11T09:42:22.642+0000] {logging_mixin.py:188} INFO - [2025-08-11T09:42:22.558+0000] {dagbag.py:350} ERROR - Failed to import: /opt/airflow/dags/twitter_love_dag.py
Traceback (most recent call last):
  File "/home/airflow/.local/lib/python3.10/site-packages/airflow/models/dagbag.py", line 346, in parse
    loader.exec_module(new_module)
  File "<frozen importlib._bootstrap_external>", line 883, in exec_module
  File "<frozen importlib._bootstrap>", line 241, in _call_with_frames_removed
  File "/opt/airflow/dags/twitter_love_dag.py", line 15, in <module>
    with open(CREDENTIALS_PATH) as f:
FileNotFoundError: [Errno 2] No such file or directory: '/opt/airflow/data/twitter_api.json'
[2025-08-11T09:42:22.652+0000] {processor.py:842} WARNING - No viable dags retrieved from /opt/airflow/dags/twitter_love_dag.py
[2025-08-11T09:42:22.706+0000] {processor.py:183} INFO - Processing /opt/airflow/dags/twitter_love_dag.py took 1.216 seconds
[2025-08-11T09:42:53.002+0000] {processor.py:161} INFO - Started process (PID=163) to work on /opt/airflow/dags/twitter_love_dag.py
[2025-08-11T09:42:53.004+0000] {processor.py:830} INFO - Processing file /opt/airflow/dags/twitter_love_dag.py for tasks to queue
[2025-08-11T09:42:53.007+0000] {logging_mixin.py:188} INFO - [2025-08-11T09:42:53.006+0000] {dagbag.py:540} INFO - Filling up the DagBag from /opt/airflow/dags/twitter_love_dag.py
[2025-08-11T09:42:53.445+0000] {logging_mixin.py:188} INFO - [2025-08-11T09:42:53.440+0000] {dagbag.py:350} ERROR - Failed to import: /opt/airflow/dags/twitter_love_dag.py
Traceback (most recent call last):
  File "/home/airflow/.local/lib/python3.10/site-packages/airflow/models/dagbag.py", line 346, in parse
    loader.exec_module(new_module)
  File "<frozen importlib._bootstrap_external>", line 883, in exec_module
  File "<frozen importlib._bootstrap>", line 241, in _call_with_frames_removed
  File "/opt/airflow/dags/twitter_love_dag.py", line 15, in <module>
    with open(CREDENTIALS_PATH) as f:
FileNotFoundError: [Errno 2] No such file or directory: '/opt/airflow/data/twitter_api.json'
[2025-08-11T09:42:53.447+0000] {processor.py:842} WARNING - No viable dags retrieved from /opt/airflow/dags/twitter_love_dag.py
[2025-08-11T09:42:53.469+0000] {processor.py:183} INFO - Processing /opt/airflow/dags/twitter_love_dag.py took 0.474 seconds
[2025-08-11T09:43:23.943+0000] {processor.py:161} INFO - Started process (PID=169) to work on /opt/airflow/dags/twitter_love_dag.py
[2025-08-11T09:43:23.944+0000] {processor.py:830} INFO - Processing file /opt/airflow/dags/twitter_love_dag.py for tasks to queue
[2025-08-11T09:43:23.946+0000] {logging_mixin.py:188} INFO - [2025-08-11T09:43:23.946+0000] {dagbag.py:540} INFO - Filling up the DagBag from /opt/airflow/dags/twitter_love_dag.py
[2025-08-11T09:43:24.402+0000] {logging_mixin.py:188} INFO - [2025-08-11T09:43:24.336+0000] {dagbag.py:350} ERROR - Failed to import: /opt/airflow/dags/twitter_love_dag.py
Traceback (most recent call last):
  File "/home/airflow/.local/lib/python3.10/site-packages/airflow/models/dagbag.py", line 346, in parse
    loader.exec_module(new_module)
  File "<frozen importlib._bootstrap_external>", line 883, in exec_module
  File "<frozen importlib._bootstrap>", line 241, in _call_with_frames_removed
  File "/opt/airflow/dags/twitter_love_dag.py", line 15, in <module>
    with open(CREDENTIALS_PATH) as f:
FileNotFoundError: [Errno 2] No such file or directory: '/opt/airflow/data/twitter_api.json'
[2025-08-11T09:43:24.412+0000] {processor.py:842} WARNING - No viable dags retrieved from /opt/airflow/dags/twitter_love_dag.py
[2025-08-11T09:43:24.440+0000] {processor.py:183} INFO - Processing /opt/airflow/dags/twitter_love_dag.py took 0.504 seconds
[2025-08-11T09:43:55.089+0000] {processor.py:161} INFO - Started process (PID=175) to work on /opt/airflow/dags/twitter_love_dag.py
[2025-08-11T09:43:55.090+0000] {processor.py:830} INFO - Processing file /opt/airflow/dags/twitter_love_dag.py for tasks to queue
[2025-08-11T09:43:55.091+0000] {logging_mixin.py:188} INFO - [2025-08-11T09:43:55.091+0000] {dagbag.py:540} INFO - Filling up the DagBag from /opt/airflow/dags/twitter_love_dag.py
[2025-08-11T09:43:55.506+0000] {logging_mixin.py:188} INFO - [2025-08-11T09:43:55.502+0000] {dagbag.py:350} ERROR - Failed to import: /opt/airflow/dags/twitter_love_dag.py
Traceback (most recent call last):
  File "/home/airflow/.local/lib/python3.10/site-packages/airflow/models/dagbag.py", line 346, in parse
    loader.exec_module(new_module)
  File "<frozen importlib._bootstrap_external>", line 883, in exec_module
  File "<frozen importlib._bootstrap>", line 241, in _call_with_frames_removed
  File "/opt/airflow/dags/twitter_love_dag.py", line 15, in <module>
    with open(CREDENTIALS_PATH) as f:
FileNotFoundError: [Errno 2] No such file or directory: '/opt/airflow/data/twitter_api.json'
[2025-08-11T09:43:55.507+0000] {processor.py:842} WARNING - No viable dags retrieved from /opt/airflow/dags/twitter_love_dag.py
[2025-08-11T09:43:55.522+0000] {processor.py:183} INFO - Processing /opt/airflow/dags/twitter_love_dag.py took 0.438 seconds
[2025-08-11T09:44:25.859+0000] {processor.py:161} INFO - Started process (PID=181) to work on /opt/airflow/dags/twitter_love_dag.py
[2025-08-11T09:44:25.861+0000] {processor.py:830} INFO - Processing file /opt/airflow/dags/twitter_love_dag.py for tasks to queue
[2025-08-11T09:44:25.864+0000] {logging_mixin.py:188} INFO - [2025-08-11T09:44:25.864+0000] {dagbag.py:540} INFO - Filling up the DagBag from /opt/airflow/dags/twitter_love_dag.py
[2025-08-11T09:44:26.291+0000] {logging_mixin.py:188} INFO - [2025-08-11T09:44:26.286+0000] {dagbag.py:350} ERROR - Failed to import: /opt/airflow/dags/twitter_love_dag.py
Traceback (most recent call last):
  File "/home/airflow/.local/lib/python3.10/site-packages/airflow/models/dagbag.py", line 346, in parse
    loader.exec_module(new_module)
  File "<frozen importlib._bootstrap_external>", line 883, in exec_module
  File "<frozen importlib._bootstrap>", line 241, in _call_with_frames_removed
  File "/opt/airflow/dags/twitter_love_dag.py", line 15, in <module>
    with open(CREDENTIALS_PATH) as f:
FileNotFoundError: [Errno 2] No such file or directory: '/opt/airflow/data/twitter_api.json'
[2025-08-11T09:44:26.293+0000] {processor.py:842} WARNING - No viable dags retrieved from /opt/airflow/dags/twitter_love_dag.py
[2025-08-11T09:44:26.307+0000] {processor.py:183} INFO - Processing /opt/airflow/dags/twitter_love_dag.py took 0.456 seconds
[2025-08-11T09:44:56.896+0000] {processor.py:161} INFO - Started process (PID=187) to work on /opt/airflow/dags/twitter_love_dag.py
[2025-08-11T09:44:56.898+0000] {processor.py:830} INFO - Processing file /opt/airflow/dags/twitter_love_dag.py for tasks to queue
[2025-08-11T09:44:56.899+0000] {logging_mixin.py:188} INFO - [2025-08-11T09:44:56.899+0000] {dagbag.py:540} INFO - Filling up the DagBag from /opt/airflow/dags/twitter_love_dag.py
[2025-08-11T09:44:57.297+0000] {logging_mixin.py:188} INFO - [2025-08-11T09:44:57.291+0000] {dagbag.py:350} ERROR - Failed to import: /opt/airflow/dags/twitter_love_dag.py
Traceback (most recent call last):
  File "/home/airflow/.local/lib/python3.10/site-packages/airflow/models/dagbag.py", line 346, in parse
    loader.exec_module(new_module)
  File "<frozen importlib._bootstrap_external>", line 883, in exec_module
  File "<frozen importlib._bootstrap>", line 241, in _call_with_frames_removed
  File "/opt/airflow/dags/twitter_love_dag.py", line 15, in <module>
    with open(CREDENTIALS_PATH) as f:
FileNotFoundError: [Errno 2] No such file or directory: '/opt/airflow/data/twitter_api.json'
[2025-08-11T09:44:57.298+0000] {processor.py:842} WARNING - No viable dags retrieved from /opt/airflow/dags/twitter_love_dag.py
[2025-08-11T09:44:57.313+0000] {processor.py:183} INFO - Processing /opt/airflow/dags/twitter_love_dag.py took 0.422 seconds
[2025-08-11T09:45:27.564+0000] {processor.py:161} INFO - Started process (PID=193) to work on /opt/airflow/dags/twitter_love_dag.py
[2025-08-11T09:45:27.565+0000] {processor.py:830} INFO - Processing file /opt/airflow/dags/twitter_love_dag.py for tasks to queue
[2025-08-11T09:45:27.567+0000] {logging_mixin.py:188} INFO - [2025-08-11T09:45:27.567+0000] {dagbag.py:540} INFO - Filling up the DagBag from /opt/airflow/dags/twitter_love_dag.py
[2025-08-11T09:45:28.036+0000] {logging_mixin.py:188} INFO - [2025-08-11T09:45:28.033+0000] {dagbag.py:350} ERROR - Failed to import: /opt/airflow/dags/twitter_love_dag.py
Traceback (most recent call last):
  File "/home/airflow/.local/lib/python3.10/site-packages/airflow/models/dagbag.py", line 346, in parse
    loader.exec_module(new_module)
  File "<frozen importlib._bootstrap_external>", line 883, in exec_module
  File "<frozen importlib._bootstrap>", line 241, in _call_with_frames_removed
  File "/opt/airflow/dags/twitter_love_dag.py", line 15, in <module>
    with open(CREDENTIALS_PATH) as f:
FileNotFoundError: [Errno 2] No such file or directory: '/opt/airflow/data/twitter_api.json'
[2025-08-11T09:45:28.037+0000] {processor.py:842} WARNING - No viable dags retrieved from /opt/airflow/dags/twitter_love_dag.py
[2025-08-11T09:45:28.051+0000] {processor.py:183} INFO - Processing /opt/airflow/dags/twitter_love_dag.py took 0.493 seconds
[2025-08-11T09:45:59.014+0000] {processor.py:161} INFO - Started process (PID=199) to work on /opt/airflow/dags/twitter_love_dag.py
[2025-08-11T09:45:59.016+0000] {processor.py:830} INFO - Processing file /opt/airflow/dags/twitter_love_dag.py for tasks to queue
[2025-08-11T09:45:59.020+0000] {logging_mixin.py:188} INFO - [2025-08-11T09:45:59.020+0000] {dagbag.py:540} INFO - Filling up the DagBag from /opt/airflow/dags/twitter_love_dag.py
[2025-08-11T09:45:59.480+0000] {logging_mixin.py:188} INFO - [2025-08-11T09:45:59.461+0000] {dagbag.py:350} ERROR - Failed to import: /opt/airflow/dags/twitter_love_dag.py
Traceback (most recent call last):
  File "/home/airflow/.local/lib/python3.10/site-packages/airflow/models/dagbag.py", line 346, in parse
    loader.exec_module(new_module)
  File "<frozen importlib._bootstrap_external>", line 883, in exec_module
  File "<frozen importlib._bootstrap>", line 241, in _call_with_frames_removed
  File "/opt/airflow/dags/twitter_love_dag.py", line 15, in <module>
    with open(CREDENTIALS_PATH) as f:
FileNotFoundError: [Errno 2] No such file or directory: '/opt/airflow/data/twitter_api.json'
[2025-08-11T09:45:59.482+0000] {processor.py:842} WARNING - No viable dags retrieved from /opt/airflow/dags/twitter_love_dag.py
[2025-08-11T09:45:59.500+0000] {processor.py:183} INFO - Processing /opt/airflow/dags/twitter_love_dag.py took 0.499 seconds
[2025-08-11T09:46:30.382+0000] {processor.py:161} INFO - Started process (PID=205) to work on /opt/airflow/dags/twitter_love_dag.py
[2025-08-11T09:46:30.388+0000] {processor.py:830} INFO - Processing file /opt/airflow/dags/twitter_love_dag.py for tasks to queue
[2025-08-11T09:46:30.391+0000] {logging_mixin.py:188} INFO - [2025-08-11T09:46:30.390+0000] {dagbag.py:540} INFO - Filling up the DagBag from /opt/airflow/dags/twitter_love_dag.py
[2025-08-11T09:46:30.874+0000] {logging_mixin.py:188} INFO - [2025-08-11T09:46:30.867+0000] {dagbag.py:350} ERROR - Failed to import: /opt/airflow/dags/twitter_love_dag.py
Traceback (most recent call last):
  File "/home/airflow/.local/lib/python3.10/site-packages/airflow/models/dagbag.py", line 346, in parse
    loader.exec_module(new_module)
  File "<frozen importlib._bootstrap_external>", line 883, in exec_module
  File "<frozen importlib._bootstrap>", line 241, in _call_with_frames_removed
  File "/opt/airflow/dags/twitter_love_dag.py", line 15, in <module>
    with open(CREDENTIALS_PATH) as f:
FileNotFoundError: [Errno 2] No such file or directory: '/opt/airflow/data/twitter_api.json'
[2025-08-11T09:46:30.876+0000] {processor.py:842} WARNING - No viable dags retrieved from /opt/airflow/dags/twitter_love_dag.py
[2025-08-11T09:46:30.893+0000] {processor.py:183} INFO - Processing /opt/airflow/dags/twitter_love_dag.py took 0.518 seconds
[2025-08-11T09:47:01.082+0000] {processor.py:161} INFO - Started process (PID=211) to work on /opt/airflow/dags/twitter_love_dag.py
[2025-08-11T09:47:01.088+0000] {processor.py:830} INFO - Processing file /opt/airflow/dags/twitter_love_dag.py for tasks to queue
[2025-08-11T09:47:01.091+0000] {logging_mixin.py:188} INFO - [2025-08-11T09:47:01.091+0000] {dagbag.py:540} INFO - Filling up the DagBag from /opt/airflow/dags/twitter_love_dag.py
[2025-08-11T09:47:01.564+0000] {logging_mixin.py:188} INFO - [2025-08-11T09:47:01.555+0000] {dagbag.py:350} ERROR - Failed to import: /opt/airflow/dags/twitter_love_dag.py
Traceback (most recent call last):
  File "/home/airflow/.local/lib/python3.10/site-packages/airflow/models/dagbag.py", line 346, in parse
    loader.exec_module(new_module)
  File "<frozen importlib._bootstrap_external>", line 883, in exec_module
  File "<frozen importlib._bootstrap>", line 241, in _call_with_frames_removed
  File "/opt/airflow/dags/twitter_love_dag.py", line 15, in <module>
    with open(CREDENTIALS_PATH) as f:
FileNotFoundError: [Errno 2] No such file or directory: '/opt/airflow/data/twitter_api.json'
[2025-08-11T09:47:01.566+0000] {processor.py:842} WARNING - No viable dags retrieved from /opt/airflow/dags/twitter_love_dag.py
[2025-08-11T09:47:01.603+0000] {processor.py:183} INFO - Processing /opt/airflow/dags/twitter_love_dag.py took 0.539 seconds
[2025-08-11T09:47:31.972+0000] {processor.py:161} INFO - Started process (PID=217) to work on /opt/airflow/dags/twitter_love_dag.py
[2025-08-11T09:47:31.974+0000] {processor.py:830} INFO - Processing file /opt/airflow/dags/twitter_love_dag.py for tasks to queue
[2025-08-11T09:47:31.976+0000] {logging_mixin.py:188} INFO - [2025-08-11T09:47:31.976+0000] {dagbag.py:540} INFO - Filling up the DagBag from /opt/airflow/dags/twitter_love_dag.py
[2025-08-11T09:47:32.500+0000] {logging_mixin.py:188} INFO - [2025-08-11T09:47:32.446+0000] {dagbag.py:350} ERROR - Failed to import: /opt/airflow/dags/twitter_love_dag.py
Traceback (most recent call last):
  File "/home/airflow/.local/lib/python3.10/site-packages/airflow/models/dagbag.py", line 346, in parse
    loader.exec_module(new_module)
  File "<frozen importlib._bootstrap_external>", line 883, in exec_module
  File "<frozen importlib._bootstrap>", line 241, in _call_with_frames_removed
  File "/opt/airflow/dags/twitter_love_dag.py", line 15, in <module>
    with open(CREDENTIALS_PATH) as f:
FileNotFoundError: [Errno 2] No such file or directory: '/opt/airflow/data/twitter_api.json'
[2025-08-11T09:47:32.507+0000] {processor.py:842} WARNING - No viable dags retrieved from /opt/airflow/dags/twitter_love_dag.py
[2025-08-11T09:47:32.547+0000] {processor.py:183} INFO - Processing /opt/airflow/dags/twitter_love_dag.py took 0.581 seconds
[2025-08-11T09:48:03.188+0000] {processor.py:161} INFO - Started process (PID=223) to work on /opt/airflow/dags/twitter_love_dag.py
[2025-08-11T09:48:03.190+0000] {processor.py:830} INFO - Processing file /opt/airflow/dags/twitter_love_dag.py for tasks to queue
[2025-08-11T09:48:03.192+0000] {logging_mixin.py:188} INFO - [2025-08-11T09:48:03.191+0000] {dagbag.py:540} INFO - Filling up the DagBag from /opt/airflow/dags/twitter_love_dag.py
[2025-08-11T09:48:03.699+0000] {logging_mixin.py:188} INFO - [2025-08-11T09:48:03.695+0000] {dagbag.py:350} ERROR - Failed to import: /opt/airflow/dags/twitter_love_dag.py
Traceback (most recent call last):
  File "/home/airflow/.local/lib/python3.10/site-packages/airflow/models/dagbag.py", line 346, in parse
    loader.exec_module(new_module)
  File "<frozen importlib._bootstrap_external>", line 883, in exec_module
  File "<frozen importlib._bootstrap>", line 241, in _call_with_frames_removed
  File "/opt/airflow/dags/twitter_love_dag.py", line 15, in <module>
    with open(CREDENTIALS_PATH) as f:
FileNotFoundError: [Errno 2] No such file or directory: '/opt/airflow/data/twitter_api.json'
[2025-08-11T09:48:03.700+0000] {processor.py:842} WARNING - No viable dags retrieved from /opt/airflow/dags/twitter_love_dag.py
[2025-08-11T09:48:03.719+0000] {processor.py:183} INFO - Processing /opt/airflow/dags/twitter_love_dag.py took 0.538 seconds
[2025-08-11T09:48:34.417+0000] {processor.py:161} INFO - Started process (PID=229) to work on /opt/airflow/dags/twitter_love_dag.py
[2025-08-11T09:48:34.421+0000] {processor.py:830} INFO - Processing file /opt/airflow/dags/twitter_love_dag.py for tasks to queue
[2025-08-11T09:48:34.428+0000] {logging_mixin.py:188} INFO - [2025-08-11T09:48:34.427+0000] {dagbag.py:540} INFO - Filling up the DagBag from /opt/airflow/dags/twitter_love_dag.py
[2025-08-11T09:48:34.923+0000] {logging_mixin.py:188} INFO - [2025-08-11T09:48:34.917+0000] {dagbag.py:350} ERROR - Failed to import: /opt/airflow/dags/twitter_love_dag.py
Traceback (most recent call last):
  File "/home/airflow/.local/lib/python3.10/site-packages/airflow/models/dagbag.py", line 346, in parse
    loader.exec_module(new_module)
  File "<frozen importlib._bootstrap_external>", line 883, in exec_module
  File "<frozen importlib._bootstrap>", line 241, in _call_with_frames_removed
  File "/opt/airflow/dags/twitter_love_dag.py", line 15, in <module>
    with open(CREDENTIALS_PATH) as f:
FileNotFoundError: [Errno 2] No such file or directory: '/opt/airflow/data/twitter_api.json'
[2025-08-11T09:48:34.925+0000] {processor.py:842} WARNING - No viable dags retrieved from /opt/airflow/dags/twitter_love_dag.py
[2025-08-11T09:48:34.946+0000] {processor.py:183} INFO - Processing /opt/airflow/dags/twitter_love_dag.py took 0.537 seconds
[2025-08-11T09:49:05.857+0000] {processor.py:161} INFO - Started process (PID=235) to work on /opt/airflow/dags/twitter_love_dag.py
[2025-08-11T09:49:05.858+0000] {processor.py:830} INFO - Processing file /opt/airflow/dags/twitter_love_dag.py for tasks to queue
[2025-08-11T09:49:05.860+0000] {logging_mixin.py:188} INFO - [2025-08-11T09:49:05.860+0000] {dagbag.py:540} INFO - Filling up the DagBag from /opt/airflow/dags/twitter_love_dag.py
[2025-08-11T09:49:06.285+0000] {logging_mixin.py:188} INFO - [2025-08-11T09:49:06.280+0000] {dagbag.py:350} ERROR - Failed to import: /opt/airflow/dags/twitter_love_dag.py
Traceback (most recent call last):
  File "/home/airflow/.local/lib/python3.10/site-packages/airflow/models/dagbag.py", line 346, in parse
    loader.exec_module(new_module)
  File "<frozen importlib._bootstrap_external>", line 883, in exec_module
  File "<frozen importlib._bootstrap>", line 241, in _call_with_frames_removed
  File "/opt/airflow/dags/twitter_love_dag.py", line 15, in <module>
    with open(CREDENTIALS_PATH) as f:
FileNotFoundError: [Errno 2] No such file or directory: '/opt/airflow/data/twitter_api.json'
[2025-08-11T09:49:06.286+0000] {processor.py:842} WARNING - No viable dags retrieved from /opt/airflow/dags/twitter_love_dag.py
[2025-08-11T09:49:06.307+0000] {processor.py:183} INFO - Processing /opt/airflow/dags/twitter_love_dag.py took 0.456 seconds
[2025-08-11T09:49:36.864+0000] {processor.py:161} INFO - Started process (PID=241) to work on /opt/airflow/dags/twitter_love_dag.py
[2025-08-11T09:49:36.866+0000] {processor.py:830} INFO - Processing file /opt/airflow/dags/twitter_love_dag.py for tasks to queue
[2025-08-11T09:49:36.869+0000] {logging_mixin.py:188} INFO - [2025-08-11T09:49:36.868+0000] {dagbag.py:540} INFO - Filling up the DagBag from /opt/airflow/dags/twitter_love_dag.py
[2025-08-11T09:49:37.319+0000] {logging_mixin.py:188} INFO - [2025-08-11T09:49:37.316+0000] {dagbag.py:350} ERROR - Failed to import: /opt/airflow/dags/twitter_love_dag.py
Traceback (most recent call last):
  File "/home/airflow/.local/lib/python3.10/site-packages/airflow/models/dagbag.py", line 346, in parse
    loader.exec_module(new_module)
  File "<frozen importlib._bootstrap_external>", line 883, in exec_module
  File "<frozen importlib._bootstrap>", line 241, in _call_with_frames_removed
  File "/opt/airflow/dags/twitter_love_dag.py", line 15, in <module>
    with open(CREDENTIALS_PATH) as f:
FileNotFoundError: [Errno 2] No such file or directory: '/opt/airflow/data/twitter_api.json'
[2025-08-11T09:49:37.321+0000] {processor.py:842} WARNING - No viable dags retrieved from /opt/airflow/dags/twitter_love_dag.py
[2025-08-11T09:49:37.344+0000] {processor.py:183} INFO - Processing /opt/airflow/dags/twitter_love_dag.py took 0.487 seconds
[2025-08-11T09:50:07.716+0000] {processor.py:161} INFO - Started process (PID=247) to work on /opt/airflow/dags/twitter_love_dag.py
[2025-08-11T09:50:07.718+0000] {processor.py:830} INFO - Processing file /opt/airflow/dags/twitter_love_dag.py for tasks to queue
[2025-08-11T09:50:07.720+0000] {logging_mixin.py:188} INFO - [2025-08-11T09:50:07.720+0000] {dagbag.py:540} INFO - Filling up the DagBag from /opt/airflow/dags/twitter_love_dag.py
[2025-08-11T09:50:08.258+0000] {logging_mixin.py:188} INFO - [2025-08-11T09:50:08.253+0000] {dagbag.py:350} ERROR - Failed to import: /opt/airflow/dags/twitter_love_dag.py
Traceback (most recent call last):
  File "/home/airflow/.local/lib/python3.10/site-packages/airflow/models/dagbag.py", line 346, in parse
    loader.exec_module(new_module)
  File "<frozen importlib._bootstrap_external>", line 883, in exec_module
  File "<frozen importlib._bootstrap>", line 241, in _call_with_frames_removed
  File "/opt/airflow/dags/twitter_love_dag.py", line 15, in <module>
    with open(CREDENTIALS_PATH) as f:
FileNotFoundError: [Errno 2] No such file or directory: '/opt/airflow/data/twitter_api.json'
[2025-08-11T09:50:08.261+0000] {processor.py:842} WARNING - No viable dags retrieved from /opt/airflow/dags/twitter_love_dag.py
[2025-08-11T09:50:08.290+0000] {processor.py:183} INFO - Processing /opt/airflow/dags/twitter_love_dag.py took 0.587 seconds
[2025-08-11T09:50:38.542+0000] {processor.py:161} INFO - Started process (PID=253) to work on /opt/airflow/dags/twitter_love_dag.py
[2025-08-11T09:50:38.543+0000] {processor.py:830} INFO - Processing file /opt/airflow/dags/twitter_love_dag.py for tasks to queue
[2025-08-11T09:50:38.545+0000] {logging_mixin.py:188} INFO - [2025-08-11T09:50:38.545+0000] {dagbag.py:540} INFO - Filling up the DagBag from /opt/airflow/dags/twitter_love_dag.py
[2025-08-11T09:50:38.938+0000] {logging_mixin.py:188} INFO - [2025-08-11T09:50:38.933+0000] {dagbag.py:350} ERROR - Failed to import: /opt/airflow/dags/twitter_love_dag.py
Traceback (most recent call last):
  File "/home/airflow/.local/lib/python3.10/site-packages/airflow/models/dagbag.py", line 346, in parse
    loader.exec_module(new_module)
  File "<frozen importlib._bootstrap_external>", line 883, in exec_module
  File "<frozen importlib._bootstrap>", line 241, in _call_with_frames_removed
  File "/opt/airflow/dags/twitter_love_dag.py", line 15, in <module>
    with open(CREDENTIALS_PATH) as f:
FileNotFoundError: [Errno 2] No such file or directory: '/opt/airflow/data/twitter_api.json'
[2025-08-11T09:50:38.939+0000] {processor.py:842} WARNING - No viable dags retrieved from /opt/airflow/dags/twitter_love_dag.py
[2025-08-11T09:50:38.952+0000] {processor.py:183} INFO - Processing /opt/airflow/dags/twitter_love_dag.py took 0.416 seconds
[2025-08-11T09:51:10.018+0000] {processor.py:161} INFO - Started process (PID=259) to work on /opt/airflow/dags/twitter_love_dag.py
[2025-08-11T09:51:10.019+0000] {processor.py:830} INFO - Processing file /opt/airflow/dags/twitter_love_dag.py for tasks to queue
[2025-08-11T09:51:10.021+0000] {logging_mixin.py:188} INFO - [2025-08-11T09:51:10.021+0000] {dagbag.py:540} INFO - Filling up the DagBag from /opt/airflow/dags/twitter_love_dag.py
[2025-08-11T09:51:10.607+0000] {logging_mixin.py:188} INFO - [2025-08-11T09:51:10.602+0000] {dagbag.py:350} ERROR - Failed to import: /opt/airflow/dags/twitter_love_dag.py
Traceback (most recent call last):
  File "/home/airflow/.local/lib/python3.10/site-packages/airflow/models/dagbag.py", line 346, in parse
    loader.exec_module(new_module)
  File "<frozen importlib._bootstrap_external>", line 883, in exec_module
  File "<frozen importlib._bootstrap>", line 241, in _call_with_frames_removed
  File "/opt/airflow/dags/twitter_love_dag.py", line 15, in <module>
    with open(CREDENTIALS_PATH) as f:
FileNotFoundError: [Errno 2] No such file or directory: '/opt/airflow/data/twitter_api.json'
[2025-08-11T09:51:10.609+0000] {processor.py:842} WARNING - No viable dags retrieved from /opt/airflow/dags/twitter_love_dag.py
[2025-08-11T09:51:10.740+0000] {processor.py:183} INFO - Processing /opt/airflow/dags/twitter_love_dag.py took 0.732 seconds
[2025-08-11T09:51:41.132+0000] {processor.py:161} INFO - Started process (PID=265) to work on /opt/airflow/dags/twitter_love_dag.py
[2025-08-11T09:51:41.134+0000] {processor.py:830} INFO - Processing file /opt/airflow/dags/twitter_love_dag.py for tasks to queue
[2025-08-11T09:51:41.137+0000] {logging_mixin.py:188} INFO - [2025-08-11T09:51:41.136+0000] {dagbag.py:540} INFO - Filling up the DagBag from /opt/airflow/dags/twitter_love_dag.py
[2025-08-11T09:51:42.806+0000] {logging_mixin.py:188} INFO - [2025-08-11T09:51:42.796+0000] {dagbag.py:350} ERROR - Failed to import: /opt/airflow/dags/twitter_love_dag.py
Traceback (most recent call last):
  File "/home/airflow/.local/lib/python3.10/site-packages/airflow/models/dagbag.py", line 346, in parse
    loader.exec_module(new_module)
  File "<frozen importlib._bootstrap_external>", line 883, in exec_module
  File "<frozen importlib._bootstrap>", line 241, in _call_with_frames_removed
  File "/opt/airflow/dags/twitter_love_dag.py", line 15, in <module>
    with open(CREDENTIALS_PATH) as f:
FileNotFoundError: [Errno 2] No such file or directory: '/opt/airflow/data/twitter_api.json'
[2025-08-11T09:51:42.808+0000] {processor.py:842} WARNING - No viable dags retrieved from /opt/airflow/dags/twitter_love_dag.py
[2025-08-11T09:51:42.833+0000] {processor.py:183} INFO - Processing /opt/airflow/dags/twitter_love_dag.py took 1.716 seconds
[2025-08-11T09:52:12.910+0000] {processor.py:161} INFO - Started process (PID=271) to work on /opt/airflow/dags/twitter_love_dag.py
[2025-08-11T09:52:12.912+0000] {processor.py:830} INFO - Processing file /opt/airflow/dags/twitter_love_dag.py for tasks to queue
[2025-08-11T09:52:12.915+0000] {logging_mixin.py:188} INFO - [2025-08-11T09:52:12.915+0000] {dagbag.py:540} INFO - Filling up the DagBag from /opt/airflow/dags/twitter_love_dag.py
[2025-08-11T09:52:13.415+0000] {logging_mixin.py:188} INFO - [2025-08-11T09:52:13.410+0000] {dagbag.py:350} ERROR - Failed to import: /opt/airflow/dags/twitter_love_dag.py
Traceback (most recent call last):
  File "/home/airflow/.local/lib/python3.10/site-packages/airflow/models/dagbag.py", line 346, in parse
    loader.exec_module(new_module)
  File "<frozen importlib._bootstrap_external>", line 883, in exec_module
  File "<frozen importlib._bootstrap>", line 241, in _call_with_frames_removed
  File "/opt/airflow/dags/twitter_love_dag.py", line 15, in <module>
    with open(CREDENTIALS_PATH) as f:
FileNotFoundError: [Errno 2] No such file or directory: '/opt/airflow/data/twitter_api.json'
[2025-08-11T09:52:13.416+0000] {processor.py:842} WARNING - No viable dags retrieved from /opt/airflow/dags/twitter_love_dag.py
[2025-08-11T09:52:13.438+0000] {processor.py:183} INFO - Processing /opt/airflow/dags/twitter_love_dag.py took 0.534 seconds
[2025-08-11T09:52:44.021+0000] {processor.py:161} INFO - Started process (PID=277) to work on /opt/airflow/dags/twitter_love_dag.py
[2025-08-11T09:52:44.023+0000] {processor.py:830} INFO - Processing file /opt/airflow/dags/twitter_love_dag.py for tasks to queue
[2025-08-11T09:52:44.027+0000] {logging_mixin.py:188} INFO - [2025-08-11T09:52:44.026+0000] {dagbag.py:540} INFO - Filling up the DagBag from /opt/airflow/dags/twitter_love_dag.py
[2025-08-11T09:52:44.578+0000] {logging_mixin.py:188} INFO - [2025-08-11T09:52:44.573+0000] {dagbag.py:350} ERROR - Failed to import: /opt/airflow/dags/twitter_love_dag.py
Traceback (most recent call last):
  File "/home/airflow/.local/lib/python3.10/site-packages/airflow/models/dagbag.py", line 346, in parse
    loader.exec_module(new_module)
  File "<frozen importlib._bootstrap_external>", line 883, in exec_module
  File "<frozen importlib._bootstrap>", line 241, in _call_with_frames_removed
  File "/opt/airflow/dags/twitter_love_dag.py", line 15, in <module>
    with open(CREDENTIALS_PATH) as f:
FileNotFoundError: [Errno 2] No such file or directory: '/opt/airflow/data/twitter_api.json'
[2025-08-11T09:52:44.579+0000] {processor.py:842} WARNING - No viable dags retrieved from /opt/airflow/dags/twitter_love_dag.py
[2025-08-11T09:52:44.607+0000] {processor.py:183} INFO - Processing /opt/airflow/dags/twitter_love_dag.py took 0.604 seconds
[2025-08-11T09:53:15.507+0000] {processor.py:161} INFO - Started process (PID=283) to work on /opt/airflow/dags/twitter_love_dag.py
[2025-08-11T09:53:15.509+0000] {processor.py:830} INFO - Processing file /opt/airflow/dags/twitter_love_dag.py for tasks to queue
[2025-08-11T09:53:15.512+0000] {logging_mixin.py:188} INFO - [2025-08-11T09:53:15.511+0000] {dagbag.py:540} INFO - Filling up the DagBag from /opt/airflow/dags/twitter_love_dag.py
[2025-08-11T09:53:16.962+0000] {logging_mixin.py:188} INFO - [2025-08-11T09:53:16.955+0000] {dagbag.py:350} ERROR - Failed to import: /opt/airflow/dags/twitter_love_dag.py
Traceback (most recent call last):
  File "/home/airflow/.local/lib/python3.10/site-packages/airflow/models/dagbag.py", line 346, in parse
    loader.exec_module(new_module)
  File "<frozen importlib._bootstrap_external>", line 883, in exec_module
  File "<frozen importlib._bootstrap>", line 241, in _call_with_frames_removed
  File "/opt/airflow/dags/twitter_love_dag.py", line 15, in <module>
    with open(CREDENTIALS_PATH) as f:
FileNotFoundError: [Errno 2] No such file or directory: '/opt/airflow/data/twitter_api.json'
[2025-08-11T09:53:16.965+0000] {processor.py:842} WARNING - No viable dags retrieved from /opt/airflow/dags/twitter_love_dag.py
[2025-08-11T09:53:17.017+0000] {processor.py:183} INFO - Processing /opt/airflow/dags/twitter_love_dag.py took 1.521 seconds
[2025-08-11T09:53:47.949+0000] {processor.py:161} INFO - Started process (PID=289) to work on /opt/airflow/dags/twitter_love_dag.py
[2025-08-11T09:53:47.950+0000] {processor.py:830} INFO - Processing file /opt/airflow/dags/twitter_love_dag.py for tasks to queue
[2025-08-11T09:53:47.952+0000] {logging_mixin.py:188} INFO - [2025-08-11T09:53:47.952+0000] {dagbag.py:540} INFO - Filling up the DagBag from /opt/airflow/dags/twitter_love_dag.py
[2025-08-11T09:53:48.373+0000] {logging_mixin.py:188} INFO - [2025-08-11T09:53:48.369+0000] {dagbag.py:350} ERROR - Failed to import: /opt/airflow/dags/twitter_love_dag.py
Traceback (most recent call last):
  File "/home/airflow/.local/lib/python3.10/site-packages/airflow/models/dagbag.py", line 346, in parse
    loader.exec_module(new_module)
  File "<frozen importlib._bootstrap_external>", line 883, in exec_module
  File "<frozen importlib._bootstrap>", line 241, in _call_with_frames_removed
  File "/opt/airflow/dags/twitter_love_dag.py", line 15, in <module>
    with open(CREDENTIALS_PATH) as f:
FileNotFoundError: [Errno 2] No such file or directory: '/opt/airflow/data/twitter_api.json'
[2025-08-11T09:53:48.374+0000] {processor.py:842} WARNING - No viable dags retrieved from /opt/airflow/dags/twitter_love_dag.py
[2025-08-11T09:53:48.394+0000] {processor.py:183} INFO - Processing /opt/airflow/dags/twitter_love_dag.py took 0.450 seconds
[2025-08-11T09:54:18.811+0000] {processor.py:161} INFO - Started process (PID=295) to work on /opt/airflow/dags/twitter_love_dag.py
[2025-08-11T09:54:18.812+0000] {processor.py:830} INFO - Processing file /opt/airflow/dags/twitter_love_dag.py for tasks to queue
[2025-08-11T09:54:18.814+0000] {logging_mixin.py:188} INFO - [2025-08-11T09:54:18.814+0000] {dagbag.py:540} INFO - Filling up the DagBag from /opt/airflow/dags/twitter_love_dag.py
[2025-08-11T09:54:19.251+0000] {logging_mixin.py:188} INFO - [2025-08-11T09:54:19.247+0000] {dagbag.py:350} ERROR - Failed to import: /opt/airflow/dags/twitter_love_dag.py
Traceback (most recent call last):
  File "/home/airflow/.local/lib/python3.10/site-packages/airflow/models/dagbag.py", line 346, in parse
    loader.exec_module(new_module)
  File "<frozen importlib._bootstrap_external>", line 883, in exec_module
  File "<frozen importlib._bootstrap>", line 241, in _call_with_frames_removed
  File "/opt/airflow/dags/twitter_love_dag.py", line 15, in <module>
    with open(CREDENTIALS_PATH) as f:
FileNotFoundError: [Errno 2] No such file or directory: '/opt/airflow/data/twitter_api.json'
[2025-08-11T09:54:19.252+0000] {processor.py:842} WARNING - No viable dags retrieved from /opt/airflow/dags/twitter_love_dag.py
[2025-08-11T09:54:19.269+0000] {processor.py:183} INFO - Processing /opt/airflow/dags/twitter_love_dag.py took 0.465 seconds
[2025-08-11T09:54:49.928+0000] {processor.py:161} INFO - Started process (PID=301) to work on /opt/airflow/dags/twitter_love_dag.py
[2025-08-11T09:54:49.929+0000] {processor.py:830} INFO - Processing file /opt/airflow/dags/twitter_love_dag.py for tasks to queue
[2025-08-11T09:54:49.931+0000] {logging_mixin.py:188} INFO - [2025-08-11T09:54:49.930+0000] {dagbag.py:540} INFO - Filling up the DagBag from /opt/airflow/dags/twitter_love_dag.py
[2025-08-11T09:54:50.409+0000] {logging_mixin.py:188} INFO - [2025-08-11T09:54:50.405+0000] {dagbag.py:350} ERROR - Failed to import: /opt/airflow/dags/twitter_love_dag.py
Traceback (most recent call last):
  File "/home/airflow/.local/lib/python3.10/site-packages/airflow/models/dagbag.py", line 346, in parse
    loader.exec_module(new_module)
  File "<frozen importlib._bootstrap_external>", line 883, in exec_module
  File "<frozen importlib._bootstrap>", line 241, in _call_with_frames_removed
  File "/opt/airflow/dags/twitter_love_dag.py", line 15, in <module>
    with open(CREDENTIALS_PATH) as f:
FileNotFoundError: [Errno 2] No such file or directory: '/opt/airflow/data/twitter_api.json'
[2025-08-11T09:54:50.411+0000] {processor.py:842} WARNING - No viable dags retrieved from /opt/airflow/dags/twitter_love_dag.py
[2025-08-11T09:54:50.430+0000] {processor.py:183} INFO - Processing /opt/airflow/dags/twitter_love_dag.py took 0.507 seconds
[2025-08-11T09:55:21.289+0000] {processor.py:161} INFO - Started process (PID=307) to work on /opt/airflow/dags/twitter_love_dag.py
[2025-08-11T09:55:21.293+0000] {processor.py:830} INFO - Processing file /opt/airflow/dags/twitter_love_dag.py for tasks to queue
[2025-08-11T09:55:21.301+0000] {logging_mixin.py:188} INFO - [2025-08-11T09:55:21.300+0000] {dagbag.py:540} INFO - Filling up the DagBag from /opt/airflow/dags/twitter_love_dag.py
[2025-08-11T09:55:23.466+0000] {logging_mixin.py:188} INFO - [2025-08-11T09:55:23.420+0000] {dagbag.py:350} ERROR - Failed to import: /opt/airflow/dags/twitter_love_dag.py
Traceback (most recent call last):
  File "/home/airflow/.local/lib/python3.10/site-packages/airflow/models/dagbag.py", line 346, in parse
    loader.exec_module(new_module)
  File "<frozen importlib._bootstrap_external>", line 883, in exec_module
  File "<frozen importlib._bootstrap>", line 241, in _call_with_frames_removed
  File "/opt/airflow/dags/twitter_love_dag.py", line 15, in <module>
    with open(CREDENTIALS_PATH) as f:
FileNotFoundError: [Errno 2] No such file or directory: '/opt/airflow/data/twitter_api.json'
[2025-08-11T09:55:23.469+0000] {processor.py:842} WARNING - No viable dags retrieved from /opt/airflow/dags/twitter_love_dag.py
[2025-08-11T09:55:23.532+0000] {processor.py:183} INFO - Processing /opt/airflow/dags/twitter_love_dag.py took 2.293 seconds
[2025-08-11T09:55:53.648+0000] {processor.py:161} INFO - Started process (PID=313) to work on /opt/airflow/dags/twitter_love_dag.py
[2025-08-11T09:55:53.650+0000] {processor.py:830} INFO - Processing file /opt/airflow/dags/twitter_love_dag.py for tasks to queue
[2025-08-11T09:55:53.652+0000] {logging_mixin.py:188} INFO - [2025-08-11T09:55:53.652+0000] {dagbag.py:540} INFO - Filling up the DagBag from /opt/airflow/dags/twitter_love_dag.py
[2025-08-11T09:55:54.173+0000] {logging_mixin.py:188} INFO - [2025-08-11T09:55:54.169+0000] {dagbag.py:350} ERROR - Failed to import: /opt/airflow/dags/twitter_love_dag.py
Traceback (most recent call last):
  File "/home/airflow/.local/lib/python3.10/site-packages/airflow/models/dagbag.py", line 346, in parse
    loader.exec_module(new_module)
  File "<frozen importlib._bootstrap_external>", line 883, in exec_module
  File "<frozen importlib._bootstrap>", line 241, in _call_with_frames_removed
  File "/opt/airflow/dags/twitter_love_dag.py", line 15, in <module>
    with open(CREDENTIALS_PATH) as f:
FileNotFoundError: [Errno 2] No such file or directory: '/opt/airflow/data/twitter_api.json'
[2025-08-11T09:55:54.174+0000] {processor.py:842} WARNING - No viable dags retrieved from /opt/airflow/dags/twitter_love_dag.py
[2025-08-11T09:55:54.192+0000] {processor.py:183} INFO - Processing /opt/airflow/dags/twitter_love_dag.py took 0.551 seconds
[2025-08-11T09:56:24.918+0000] {processor.py:161} INFO - Started process (PID=319) to work on /opt/airflow/dags/twitter_love_dag.py
[2025-08-11T09:56:24.921+0000] {processor.py:830} INFO - Processing file /opt/airflow/dags/twitter_love_dag.py for tasks to queue
[2025-08-11T09:56:24.925+0000] {logging_mixin.py:188} INFO - [2025-08-11T09:56:24.924+0000] {dagbag.py:540} INFO - Filling up the DagBag from /opt/airflow/dags/twitter_love_dag.py
[2025-08-11T09:56:25.516+0000] {logging_mixin.py:188} INFO - [2025-08-11T09:56:25.513+0000] {dagbag.py:350} ERROR - Failed to import: /opt/airflow/dags/twitter_love_dag.py
Traceback (most recent call last):
  File "/home/airflow/.local/lib/python3.10/site-packages/airflow/models/dagbag.py", line 346, in parse
    loader.exec_module(new_module)
  File "<frozen importlib._bootstrap_external>", line 883, in exec_module
  File "<frozen importlib._bootstrap>", line 241, in _call_with_frames_removed
  File "/opt/airflow/dags/twitter_love_dag.py", line 15, in <module>
    with open(CREDENTIALS_PATH) as f:
FileNotFoundError: [Errno 2] No such file or directory: '/opt/airflow/data/twitter_api.json'
[2025-08-11T09:56:25.517+0000] {processor.py:842} WARNING - No viable dags retrieved from /opt/airflow/dags/twitter_love_dag.py
[2025-08-11T09:56:25.538+0000] {processor.py:183} INFO - Processing /opt/airflow/dags/twitter_love_dag.py took 0.626 seconds
[2025-08-11T09:56:55.771+0000] {processor.py:161} INFO - Started process (PID=326) to work on /opt/airflow/dags/twitter_love_dag.py
[2025-08-11T09:56:55.772+0000] {processor.py:830} INFO - Processing file /opt/airflow/dags/twitter_love_dag.py for tasks to queue
[2025-08-11T09:56:55.774+0000] {logging_mixin.py:188} INFO - [2025-08-11T09:56:55.774+0000] {dagbag.py:540} INFO - Filling up the DagBag from /opt/airflow/dags/twitter_love_dag.py
[2025-08-11T09:56:56.292+0000] {logging_mixin.py:188} INFO - [2025-08-11T09:56:56.285+0000] {dagbag.py:350} ERROR - Failed to import: /opt/airflow/dags/twitter_love_dag.py
Traceback (most recent call last):
  File "/home/airflow/.local/lib/python3.10/site-packages/airflow/models/dagbag.py", line 346, in parse
    loader.exec_module(new_module)
  File "<frozen importlib._bootstrap_external>", line 883, in exec_module
  File "<frozen importlib._bootstrap>", line 241, in _call_with_frames_removed
  File "/opt/airflow/dags/twitter_love_dag.py", line 15, in <module>
    with open(CREDENTIALS_PATH) as f:
FileNotFoundError: [Errno 2] No such file or directory: '/opt/airflow/data/twitter_api.json'
[2025-08-11T09:56:56.294+0000] {processor.py:842} WARNING - No viable dags retrieved from /opt/airflow/dags/twitter_love_dag.py
[2025-08-11T09:56:56.315+0000] {processor.py:183} INFO - Processing /opt/airflow/dags/twitter_love_dag.py took 0.551 seconds
[2025-08-11T09:57:26.519+0000] {processor.py:161} INFO - Started process (PID=332) to work on /opt/airflow/dags/twitter_love_dag.py
[2025-08-11T09:57:26.522+0000] {processor.py:830} INFO - Processing file /opt/airflow/dags/twitter_love_dag.py for tasks to queue
[2025-08-11T09:57:26.528+0000] {logging_mixin.py:188} INFO - [2025-08-11T09:57:26.527+0000] {dagbag.py:540} INFO - Filling up the DagBag from /opt/airflow/dags/twitter_love_dag.py
[2025-08-11T09:57:28.603+0000] {logging_mixin.py:188} INFO - [2025-08-11T09:57:28.597+0000] {dagbag.py:350} ERROR - Failed to import: /opt/airflow/dags/twitter_love_dag.py
Traceback (most recent call last):
  File "/home/airflow/.local/lib/python3.10/site-packages/airflow/models/dagbag.py", line 346, in parse
    loader.exec_module(new_module)
  File "<frozen importlib._bootstrap_external>", line 883, in exec_module
  File "<frozen importlib._bootstrap>", line 241, in _call_with_frames_removed
  File "/opt/airflow/dags/twitter_love_dag.py", line 15, in <module>
    with open(CREDENTIALS_PATH) as f:
FileNotFoundError: [Errno 2] No such file or directory: '/opt/airflow/data/twitter_api.json'
[2025-08-11T09:57:28.671+0000] {processor.py:842} WARNING - No viable dags retrieved from /opt/airflow/dags/twitter_love_dag.py
[2025-08-11T09:57:28.696+0000] {processor.py:183} INFO - Processing /opt/airflow/dags/twitter_love_dag.py took 2.203 seconds
[2025-08-11T09:57:59.042+0000] {processor.py:161} INFO - Started process (PID=339) to work on /opt/airflow/dags/twitter_love_dag.py
[2025-08-11T09:57:59.044+0000] {processor.py:830} INFO - Processing file /opt/airflow/dags/twitter_love_dag.py for tasks to queue
[2025-08-11T09:57:59.046+0000] {logging_mixin.py:188} INFO - [2025-08-11T09:57:59.045+0000] {dagbag.py:540} INFO - Filling up the DagBag from /opt/airflow/dags/twitter_love_dag.py
[2025-08-11T09:58:00.555+0000] {logging_mixin.py:188} INFO - [2025-08-11T09:58:00.548+0000] {dagbag.py:350} ERROR - Failed to import: /opt/airflow/dags/twitter_love_dag.py
Traceback (most recent call last):
  File "/home/airflow/.local/lib/python3.10/site-packages/airflow/models/dagbag.py", line 346, in parse
    loader.exec_module(new_module)
  File "<frozen importlib._bootstrap_external>", line 883, in exec_module
  File "<frozen importlib._bootstrap>", line 241, in _call_with_frames_removed
  File "/opt/airflow/dags/twitter_love_dag.py", line 15, in <module>
    with open(CREDENTIALS_PATH) as f:
FileNotFoundError: [Errno 2] No such file or directory: '/opt/airflow/data/twitter_api.json'
[2025-08-11T09:58:00.556+0000] {processor.py:842} WARNING - No viable dags retrieved from /opt/airflow/dags/twitter_love_dag.py
[2025-08-11T09:58:00.584+0000] {processor.py:183} INFO - Processing /opt/airflow/dags/twitter_love_dag.py took 1.548 seconds
[2025-08-11T09:58:30.731+0000] {processor.py:161} INFO - Started process (PID=345) to work on /opt/airflow/dags/twitter_love_dag.py
[2025-08-11T09:58:30.733+0000] {processor.py:830} INFO - Processing file /opt/airflow/dags/twitter_love_dag.py for tasks to queue
[2025-08-11T09:58:30.735+0000] {logging_mixin.py:188} INFO - [2025-08-11T09:58:30.735+0000] {dagbag.py:540} INFO - Filling up the DagBag from /opt/airflow/dags/twitter_love_dag.py
[2025-08-11T09:58:32.505+0000] {logging_mixin.py:188} INFO - [2025-08-11T09:58:32.499+0000] {dagbag.py:350} ERROR - Failed to import: /opt/airflow/dags/twitter_love_dag.py
Traceback (most recent call last):
  File "/home/airflow/.local/lib/python3.10/site-packages/airflow/models/dagbag.py", line 346, in parse
    loader.exec_module(new_module)
  File "<frozen importlib._bootstrap_external>", line 883, in exec_module
  File "<frozen importlib._bootstrap>", line 241, in _call_with_frames_removed
  File "/opt/airflow/dags/twitter_love_dag.py", line 15, in <module>
    with open(CREDENTIALS_PATH) as f:
FileNotFoundError: [Errno 2] No such file or directory: '/opt/airflow/data/twitter_api.json'
[2025-08-11T09:58:32.507+0000] {processor.py:842} WARNING - No viable dags retrieved from /opt/airflow/dags/twitter_love_dag.py
[2025-08-11T09:58:32.548+0000] {processor.py:183} INFO - Processing /opt/airflow/dags/twitter_love_dag.py took 1.831 seconds
[2025-08-11T09:59:03.562+0000] {processor.py:161} INFO - Started process (PID=351) to work on /opt/airflow/dags/twitter_love_dag.py
[2025-08-11T09:59:03.577+0000] {processor.py:830} INFO - Processing file /opt/airflow/dags/twitter_love_dag.py for tasks to queue
[2025-08-11T09:59:03.584+0000] {logging_mixin.py:188} INFO - [2025-08-11T09:59:03.584+0000] {dagbag.py:540} INFO - Filling up the DagBag from /opt/airflow/dags/twitter_love_dag.py
[2025-08-11T09:59:04.544+0000] {logging_mixin.py:188} INFO - [2025-08-11T09:59:04.530+0000] {dagbag.py:350} ERROR - Failed to import: /opt/airflow/dags/twitter_love_dag.py
Traceback (most recent call last):
  File "/home/airflow/.local/lib/python3.10/site-packages/airflow/models/dagbag.py", line 346, in parse
    loader.exec_module(new_module)
  File "<frozen importlib._bootstrap_external>", line 883, in exec_module
  File "<frozen importlib._bootstrap>", line 241, in _call_with_frames_removed
  File "/opt/airflow/dags/twitter_love_dag.py", line 15, in <module>
    with open(CREDENTIALS_PATH) as f:
FileNotFoundError: [Errno 2] No such file or directory: '/opt/airflow/data/twitter_api.json'
[2025-08-11T09:59:04.545+0000] {processor.py:842} WARNING - No viable dags retrieved from /opt/airflow/dags/twitter_love_dag.py
[2025-08-11T09:59:04.619+0000] {processor.py:183} INFO - Processing /opt/airflow/dags/twitter_love_dag.py took 1.063 seconds
[2025-08-11T09:59:35.378+0000] {processor.py:161} INFO - Started process (PID=357) to work on /opt/airflow/dags/twitter_love_dag.py
[2025-08-11T09:59:35.380+0000] {processor.py:830} INFO - Processing file /opt/airflow/dags/twitter_love_dag.py for tasks to queue
[2025-08-11T09:59:35.382+0000] {logging_mixin.py:188} INFO - [2025-08-11T09:59:35.382+0000] {dagbag.py:540} INFO - Filling up the DagBag from /opt/airflow/dags/twitter_love_dag.py
[2025-08-11T09:59:36.006+0000] {logging_mixin.py:188} INFO - [2025-08-11T09:59:35.997+0000] {dagbag.py:350} ERROR - Failed to import: /opt/airflow/dags/twitter_love_dag.py
Traceback (most recent call last):
  File "/home/airflow/.local/lib/python3.10/site-packages/airflow/models/dagbag.py", line 346, in parse
    loader.exec_module(new_module)
  File "<frozen importlib._bootstrap_external>", line 883, in exec_module
  File "<frozen importlib._bootstrap>", line 241, in _call_with_frames_removed
  File "/opt/airflow/dags/twitter_love_dag.py", line 15, in <module>
    with open(CREDENTIALS_PATH) as f:
FileNotFoundError: [Errno 2] No such file or directory: '/opt/airflow/data/twitter_api.json'
[2025-08-11T09:59:36.008+0000] {processor.py:842} WARNING - No viable dags retrieved from /opt/airflow/dags/twitter_love_dag.py
[2025-08-11T09:59:36.029+0000] {processor.py:183} INFO - Processing /opt/airflow/dags/twitter_love_dag.py took 0.661 seconds
[2025-08-11T10:00:06.947+0000] {processor.py:161} INFO - Started process (PID=363) to work on /opt/airflow/dags/twitter_love_dag.py
[2025-08-11T10:00:06.950+0000] {processor.py:830} INFO - Processing file /opt/airflow/dags/twitter_love_dag.py for tasks to queue
[2025-08-11T10:00:06.955+0000] {logging_mixin.py:188} INFO - [2025-08-11T10:00:06.954+0000] {dagbag.py:540} INFO - Filling up the DagBag from /opt/airflow/dags/twitter_love_dag.py
[2025-08-11T10:00:07.520+0000] {logging_mixin.py:188} INFO - [2025-08-11T10:00:07.513+0000] {dagbag.py:350} ERROR - Failed to import: /opt/airflow/dags/twitter_love_dag.py
Traceback (most recent call last):
  File "/home/airflow/.local/lib/python3.10/site-packages/airflow/models/dagbag.py", line 346, in parse
    loader.exec_module(new_module)
  File "<frozen importlib._bootstrap_external>", line 883, in exec_module
  File "<frozen importlib._bootstrap>", line 241, in _call_with_frames_removed
  File "/opt/airflow/dags/twitter_love_dag.py", line 15, in <module>
    with open(CREDENTIALS_PATH) as f:
FileNotFoundError: [Errno 2] No such file or directory: '/opt/airflow/data/twitter_api.json'
[2025-08-11T10:00:07.522+0000] {processor.py:842} WARNING - No viable dags retrieved from /opt/airflow/dags/twitter_love_dag.py
[2025-08-11T10:00:07.546+0000] {processor.py:183} INFO - Processing /opt/airflow/dags/twitter_love_dag.py took 0.609 seconds
[2025-08-11T10:00:38.331+0000] {processor.py:161} INFO - Started process (PID=369) to work on /opt/airflow/dags/twitter_love_dag.py
[2025-08-11T10:00:38.332+0000] {processor.py:830} INFO - Processing file /opt/airflow/dags/twitter_love_dag.py for tasks to queue
[2025-08-11T10:00:38.334+0000] {logging_mixin.py:188} INFO - [2025-08-11T10:00:38.333+0000] {dagbag.py:540} INFO - Filling up the DagBag from /opt/airflow/dags/twitter_love_dag.py
[2025-08-11T10:00:38.918+0000] {logging_mixin.py:188} INFO - [2025-08-11T10:00:38.911+0000] {dagbag.py:350} ERROR - Failed to import: /opt/airflow/dags/twitter_love_dag.py
Traceback (most recent call last):
  File "/home/airflow/.local/lib/python3.10/site-packages/airflow/models/dagbag.py", line 346, in parse
    loader.exec_module(new_module)
  File "<frozen importlib._bootstrap_external>", line 883, in exec_module
  File "<frozen importlib._bootstrap>", line 241, in _call_with_frames_removed
  File "/opt/airflow/dags/twitter_love_dag.py", line 15, in <module>
    with open(CREDENTIALS_PATH) as f:
FileNotFoundError: [Errno 2] No such file or directory: '/opt/airflow/data/twitter_api.json'
[2025-08-11T10:00:38.920+0000] {processor.py:842} WARNING - No viable dags retrieved from /opt/airflow/dags/twitter_love_dag.py
[2025-08-11T10:00:38.945+0000] {processor.py:183} INFO - Processing /opt/airflow/dags/twitter_love_dag.py took 0.619 seconds
[2025-08-11T10:01:09.669+0000] {processor.py:161} INFO - Started process (PID=375) to work on /opt/airflow/dags/twitter_love_dag.py
[2025-08-11T10:01:09.670+0000] {processor.py:830} INFO - Processing file /opt/airflow/dags/twitter_love_dag.py for tasks to queue
[2025-08-11T10:01:09.673+0000] {logging_mixin.py:188} INFO - [2025-08-11T10:01:09.672+0000] {dagbag.py:540} INFO - Filling up the DagBag from /opt/airflow/dags/twitter_love_dag.py
[2025-08-11T10:01:10.065+0000] {logging_mixin.py:188} INFO - [2025-08-11T10:01:10.061+0000] {dagbag.py:350} ERROR - Failed to import: /opt/airflow/dags/twitter_love_dag.py
Traceback (most recent call last):
  File "/home/airflow/.local/lib/python3.10/site-packages/airflow/models/dagbag.py", line 346, in parse
    loader.exec_module(new_module)
  File "<frozen importlib._bootstrap_external>", line 883, in exec_module
  File "<frozen importlib._bootstrap>", line 241, in _call_with_frames_removed
  File "/opt/airflow/dags/twitter_love_dag.py", line 15, in <module>
    with open(CREDENTIALS_PATH) as f:
FileNotFoundError: [Errno 2] No such file or directory: '/opt/airflow/data/twitter_api.json'
[2025-08-11T10:01:10.066+0000] {processor.py:842} WARNING - No viable dags retrieved from /opt/airflow/dags/twitter_love_dag.py
[2025-08-11T10:01:10.079+0000] {processor.py:183} INFO - Processing /opt/airflow/dags/twitter_love_dag.py took 0.418 seconds
[2025-08-11T10:01:40.283+0000] {processor.py:161} INFO - Started process (PID=381) to work on /opt/airflow/dags/twitter_love_dag.py
[2025-08-11T10:01:40.284+0000] {processor.py:830} INFO - Processing file /opt/airflow/dags/twitter_love_dag.py for tasks to queue
[2025-08-11T10:01:40.286+0000] {logging_mixin.py:188} INFO - [2025-08-11T10:01:40.286+0000] {dagbag.py:540} INFO - Filling up the DagBag from /opt/airflow/dags/twitter_love_dag.py
[2025-08-11T10:01:40.670+0000] {logging_mixin.py:188} INFO - [2025-08-11T10:01:40.666+0000] {dagbag.py:350} ERROR - Failed to import: /opt/airflow/dags/twitter_love_dag.py
Traceback (most recent call last):
  File "/home/airflow/.local/lib/python3.10/site-packages/airflow/models/dagbag.py", line 346, in parse
    loader.exec_module(new_module)
  File "<frozen importlib._bootstrap_external>", line 883, in exec_module
  File "<frozen importlib._bootstrap>", line 241, in _call_with_frames_removed
  File "/opt/airflow/dags/twitter_love_dag.py", line 15, in <module>
    with open(CREDENTIALS_PATH) as f:
FileNotFoundError: [Errno 2] No such file or directory: '/opt/airflow/data/twitter_api.json'
[2025-08-11T10:01:40.672+0000] {processor.py:842} WARNING - No viable dags retrieved from /opt/airflow/dags/twitter_love_dag.py
[2025-08-11T10:01:40.687+0000] {processor.py:183} INFO - Processing /opt/airflow/dags/twitter_love_dag.py took 0.410 seconds
[2025-08-11T10:02:11.260+0000] {processor.py:161} INFO - Started process (PID=387) to work on /opt/airflow/dags/twitter_love_dag.py
[2025-08-11T10:02:11.261+0000] {processor.py:830} INFO - Processing file /opt/airflow/dags/twitter_love_dag.py for tasks to queue
[2025-08-11T10:02:11.262+0000] {logging_mixin.py:188} INFO - [2025-08-11T10:02:11.262+0000] {dagbag.py:540} INFO - Filling up the DagBag from /opt/airflow/dags/twitter_love_dag.py
[2025-08-11T10:02:11.614+0000] {logging_mixin.py:188} INFO - [2025-08-11T10:02:11.603+0000] {dagbag.py:350} ERROR - Failed to import: /opt/airflow/dags/twitter_love_dag.py
Traceback (most recent call last):
  File "/home/airflow/.local/lib/python3.10/site-packages/airflow/models/dagbag.py", line 346, in parse
    loader.exec_module(new_module)
  File "<frozen importlib._bootstrap_external>", line 883, in exec_module
  File "<frozen importlib._bootstrap>", line 241, in _call_with_frames_removed
  File "/opt/airflow/dags/twitter_love_dag.py", line 15, in <module>
    with open(CREDENTIALS_PATH) as f:
FileNotFoundError: [Errno 2] No such file or directory: '/opt/airflow/data/twitter_api.json'
[2025-08-11T10:02:11.615+0000] {processor.py:842} WARNING - No viable dags retrieved from /opt/airflow/dags/twitter_love_dag.py
[2025-08-11T10:02:11.628+0000] {processor.py:183} INFO - Processing /opt/airflow/dags/twitter_love_dag.py took 0.372 seconds
[2025-08-11T10:02:42.085+0000] {processor.py:161} INFO - Started process (PID=393) to work on /opt/airflow/dags/twitter_love_dag.py
[2025-08-11T10:02:42.092+0000] {processor.py:830} INFO - Processing file /opt/airflow/dags/twitter_love_dag.py for tasks to queue
[2025-08-11T10:02:42.114+0000] {logging_mixin.py:188} INFO - [2025-08-11T10:02:42.113+0000] {dagbag.py:540} INFO - Filling up the DagBag from /opt/airflow/dags/twitter_love_dag.py
[2025-08-11T10:02:42.694+0000] {logging_mixin.py:188} INFO - [2025-08-11T10:02:42.641+0000] {dagbag.py:350} ERROR - Failed to import: /opt/airflow/dags/twitter_love_dag.py
Traceback (most recent call last):
  File "/home/airflow/.local/lib/python3.10/site-packages/airflow/models/dagbag.py", line 346, in parse
    loader.exec_module(new_module)
  File "<frozen importlib._bootstrap_external>", line 883, in exec_module
  File "<frozen importlib._bootstrap>", line 241, in _call_with_frames_removed
  File "/opt/airflow/dags/twitter_love_dag.py", line 15, in <module>
    with open(CREDENTIALS_PATH) as f:
FileNotFoundError: [Errno 2] No such file or directory: '/opt/airflow/data/twitter_api.json'
[2025-08-11T10:02:42.713+0000] {processor.py:842} WARNING - No viable dags retrieved from /opt/airflow/dags/twitter_love_dag.py
[2025-08-11T10:02:42.755+0000] {processor.py:183} INFO - Processing /opt/airflow/dags/twitter_love_dag.py took 0.676 seconds
[2025-08-11T10:03:12.981+0000] {processor.py:161} INFO - Started process (PID=399) to work on /opt/airflow/dags/twitter_love_dag.py
[2025-08-11T10:03:12.982+0000] {processor.py:830} INFO - Processing file /opt/airflow/dags/twitter_love_dag.py for tasks to queue
[2025-08-11T10:03:12.984+0000] {logging_mixin.py:188} INFO - [2025-08-11T10:03:12.984+0000] {dagbag.py:540} INFO - Filling up the DagBag from /opt/airflow/dags/twitter_love_dag.py
[2025-08-11T10:03:13.368+0000] {logging_mixin.py:188} INFO - [2025-08-11T10:03:13.365+0000] {dagbag.py:350} ERROR - Failed to import: /opt/airflow/dags/twitter_love_dag.py
Traceback (most recent call last):
  File "/home/airflow/.local/lib/python3.10/site-packages/airflow/models/dagbag.py", line 346, in parse
    loader.exec_module(new_module)
  File "<frozen importlib._bootstrap_external>", line 883, in exec_module
  File "<frozen importlib._bootstrap>", line 241, in _call_with_frames_removed
  File "/opt/airflow/dags/twitter_love_dag.py", line 15, in <module>
    with open(CREDENTIALS_PATH) as f:
FileNotFoundError: [Errno 2] No such file or directory: '/opt/airflow/data/twitter_api.json'
[2025-08-11T10:03:13.369+0000] {processor.py:842} WARNING - No viable dags retrieved from /opt/airflow/dags/twitter_love_dag.py
[2025-08-11T10:03:13.382+0000] {processor.py:183} INFO - Processing /opt/airflow/dags/twitter_love_dag.py took 0.406 seconds
[2025-08-11T10:03:43.630+0000] {processor.py:161} INFO - Started process (PID=405) to work on /opt/airflow/dags/twitter_love_dag.py
[2025-08-11T10:03:43.632+0000] {processor.py:830} INFO - Processing file /opt/airflow/dags/twitter_love_dag.py for tasks to queue
[2025-08-11T10:03:43.636+0000] {logging_mixin.py:188} INFO - [2025-08-11T10:03:43.635+0000] {dagbag.py:540} INFO - Filling up the DagBag from /opt/airflow/dags/twitter_love_dag.py
[2025-08-11T10:03:44.567+0000] {logging_mixin.py:188} INFO - [2025-08-11T10:03:44.539+0000] {dagbag.py:350} ERROR - Failed to import: /opt/airflow/dags/twitter_love_dag.py
Traceback (most recent call last):
  File "/home/airflow/.local/lib/python3.10/site-packages/airflow/models/dagbag.py", line 346, in parse
    loader.exec_module(new_module)
  File "<frozen importlib._bootstrap_external>", line 883, in exec_module
  File "<frozen importlib._bootstrap>", line 241, in _call_with_frames_removed
  File "/opt/airflow/dags/twitter_love_dag.py", line 15, in <module>
    with open(CREDENTIALS_PATH) as f:
FileNotFoundError: [Errno 2] No such file or directory: '/opt/airflow/data/twitter_api.json'
[2025-08-11T10:03:44.586+0000] {processor.py:842} WARNING - No viable dags retrieved from /opt/airflow/dags/twitter_love_dag.py
[2025-08-11T10:03:44.625+0000] {processor.py:183} INFO - Processing /opt/airflow/dags/twitter_love_dag.py took 1.003 seconds
[2025-08-11T10:04:15.019+0000] {processor.py:161} INFO - Started process (PID=411) to work on /opt/airflow/dags/twitter_love_dag.py
[2025-08-11T10:04:15.021+0000] {processor.py:830} INFO - Processing file /opt/airflow/dags/twitter_love_dag.py for tasks to queue
[2025-08-11T10:04:15.022+0000] {logging_mixin.py:188} INFO - [2025-08-11T10:04:15.022+0000] {dagbag.py:540} INFO - Filling up the DagBag from /opt/airflow/dags/twitter_love_dag.py
[2025-08-11T10:04:15.397+0000] {logging_mixin.py:188} INFO - [2025-08-11T10:04:15.394+0000] {dagbag.py:350} ERROR - Failed to import: /opt/airflow/dags/twitter_love_dag.py
Traceback (most recent call last):
  File "/home/airflow/.local/lib/python3.10/site-packages/airflow/models/dagbag.py", line 346, in parse
    loader.exec_module(new_module)
  File "<frozen importlib._bootstrap_external>", line 883, in exec_module
  File "<frozen importlib._bootstrap>", line 241, in _call_with_frames_removed
  File "/opt/airflow/dags/twitter_love_dag.py", line 15, in <module>
    with open(CREDENTIALS_PATH) as f:
FileNotFoundError: [Errno 2] No such file or directory: '/opt/airflow/data/twitter_api.json'
[2025-08-11T10:04:15.398+0000] {processor.py:842} WARNING - No viable dags retrieved from /opt/airflow/dags/twitter_love_dag.py
[2025-08-11T10:04:15.411+0000] {processor.py:183} INFO - Processing /opt/airflow/dags/twitter_love_dag.py took 0.398 seconds
[2025-08-11T10:04:46.119+0000] {processor.py:161} INFO - Started process (PID=417) to work on /opt/airflow/dags/twitter_love_dag.py
[2025-08-11T10:04:46.120+0000] {processor.py:830} INFO - Processing file /opt/airflow/dags/twitter_love_dag.py for tasks to queue
[2025-08-11T10:04:46.122+0000] {logging_mixin.py:188} INFO - [2025-08-11T10:04:46.122+0000] {dagbag.py:540} INFO - Filling up the DagBag from /opt/airflow/dags/twitter_love_dag.py
[2025-08-11T10:04:46.578+0000] {logging_mixin.py:188} INFO - [2025-08-11T10:04:46.569+0000] {dagbag.py:350} ERROR - Failed to import: /opt/airflow/dags/twitter_love_dag.py
Traceback (most recent call last):
  File "/home/airflow/.local/lib/python3.10/site-packages/airflow/models/dagbag.py", line 346, in parse
    loader.exec_module(new_module)
  File "<frozen importlib._bootstrap_external>", line 883, in exec_module
  File "<frozen importlib._bootstrap>", line 241, in _call_with_frames_removed
  File "/opt/airflow/dags/twitter_love_dag.py", line 15, in <module>
    with open(CREDENTIALS_PATH) as f:
FileNotFoundError: [Errno 2] No such file or directory: '/opt/airflow/data/twitter_api.json'
[2025-08-11T10:04:46.583+0000] {processor.py:842} WARNING - No viable dags retrieved from /opt/airflow/dags/twitter_love_dag.py
[2025-08-11T10:04:46.599+0000] {processor.py:183} INFO - Processing /opt/airflow/dags/twitter_love_dag.py took 0.487 seconds
[2025-08-11T10:05:17.159+0000] {processor.py:161} INFO - Started process (PID=423) to work on /opt/airflow/dags/twitter_love_dag.py
[2025-08-11T10:05:17.162+0000] {processor.py:830} INFO - Processing file /opt/airflow/dags/twitter_love_dag.py for tasks to queue
[2025-08-11T10:05:17.165+0000] {logging_mixin.py:188} INFO - [2025-08-11T10:05:17.164+0000] {dagbag.py:540} INFO - Filling up the DagBag from /opt/airflow/dags/twitter_love_dag.py
[2025-08-11T10:05:17.561+0000] {logging_mixin.py:188} INFO - [2025-08-11T10:05:17.554+0000] {dagbag.py:350} ERROR - Failed to import: /opt/airflow/dags/twitter_love_dag.py
Traceback (most recent call last):
  File "/home/airflow/.local/lib/python3.10/site-packages/airflow/models/dagbag.py", line 346, in parse
    loader.exec_module(new_module)
  File "<frozen importlib._bootstrap_external>", line 883, in exec_module
  File "<frozen importlib._bootstrap>", line 241, in _call_with_frames_removed
  File "/opt/airflow/dags/twitter_love_dag.py", line 15, in <module>
    with open(CREDENTIALS_PATH) as f:
FileNotFoundError: [Errno 2] No such file or directory: '/opt/airflow/data/twitter_api.json'
[2025-08-11T10:05:17.563+0000] {processor.py:842} WARNING - No viable dags retrieved from /opt/airflow/dags/twitter_love_dag.py
[2025-08-11T10:05:17.578+0000] {processor.py:183} INFO - Processing /opt/airflow/dags/twitter_love_dag.py took 0.431 seconds
[2025-08-11T10:05:47.983+0000] {processor.py:161} INFO - Started process (PID=429) to work on /opt/airflow/dags/twitter_love_dag.py
[2025-08-11T10:05:47.987+0000] {processor.py:830} INFO - Processing file /opt/airflow/dags/twitter_love_dag.py for tasks to queue
[2025-08-11T10:05:47.990+0000] {logging_mixin.py:188} INFO - [2025-08-11T10:05:47.990+0000] {dagbag.py:540} INFO - Filling up the DagBag from /opt/airflow/dags/twitter_love_dag.py
[2025-08-11T10:05:48.407+0000] {logging_mixin.py:188} INFO - [2025-08-11T10:05:48.398+0000] {dagbag.py:350} ERROR - Failed to import: /opt/airflow/dags/twitter_love_dag.py
Traceback (most recent call last):
  File "/home/airflow/.local/lib/python3.10/site-packages/airflow/models/dagbag.py", line 346, in parse
    loader.exec_module(new_module)
  File "<frozen importlib._bootstrap_external>", line 883, in exec_module
  File "<frozen importlib._bootstrap>", line 241, in _call_with_frames_removed
  File "/opt/airflow/dags/twitter_love_dag.py", line 15, in <module>
    with open(CREDENTIALS_PATH) as f:
FileNotFoundError: [Errno 2] No such file or directory: '/opt/airflow/data/twitter_api.json'
[2025-08-11T10:05:48.409+0000] {processor.py:842} WARNING - No viable dags retrieved from /opt/airflow/dags/twitter_love_dag.py
[2025-08-11T10:05:48.423+0000] {processor.py:183} INFO - Processing /opt/airflow/dags/twitter_love_dag.py took 0.452 seconds
[2025-08-11T10:06:19.663+0000] {processor.py:161} INFO - Started process (PID=435) to work on /opt/airflow/dags/twitter_love_dag.py
[2025-08-11T10:06:19.664+0000] {processor.py:830} INFO - Processing file /opt/airflow/dags/twitter_love_dag.py for tasks to queue
[2025-08-11T10:06:19.667+0000] {logging_mixin.py:188} INFO - [2025-08-11T10:06:19.667+0000] {dagbag.py:540} INFO - Filling up the DagBag from /opt/airflow/dags/twitter_love_dag.py
[2025-08-11T10:06:20.037+0000] {logging_mixin.py:188} INFO - [2025-08-11T10:06:20.032+0000] {dagbag.py:350} ERROR - Failed to import: /opt/airflow/dags/twitter_love_dag.py
Traceback (most recent call last):
  File "/home/airflow/.local/lib/python3.10/site-packages/airflow/models/dagbag.py", line 346, in parse
    loader.exec_module(new_module)
  File "<frozen importlib._bootstrap_external>", line 883, in exec_module
  File "<frozen importlib._bootstrap>", line 241, in _call_with_frames_removed
  File "/opt/airflow/dags/twitter_love_dag.py", line 15, in <module>
    with open(CREDENTIALS_PATH) as f:
FileNotFoundError: [Errno 2] No such file or directory: '/opt/airflow/data/twitter_api.json'
[2025-08-11T10:06:20.039+0000] {processor.py:842} WARNING - No viable dags retrieved from /opt/airflow/dags/twitter_love_dag.py
[2025-08-11T10:06:20.052+0000] {processor.py:183} INFO - Processing /opt/airflow/dags/twitter_love_dag.py took 0.393 seconds
[2025-08-11T10:06:50.414+0000] {processor.py:161} INFO - Started process (PID=441) to work on /opt/airflow/dags/twitter_love_dag.py
[2025-08-11T10:06:50.416+0000] {processor.py:830} INFO - Processing file /opt/airflow/dags/twitter_love_dag.py for tasks to queue
[2025-08-11T10:06:50.418+0000] {logging_mixin.py:188} INFO - [2025-08-11T10:06:50.418+0000] {dagbag.py:540} INFO - Filling up the DagBag from /opt/airflow/dags/twitter_love_dag.py
[2025-08-11T10:06:50.842+0000] {logging_mixin.py:188} INFO - [2025-08-11T10:06:50.772+0000] {dagbag.py:350} ERROR - Failed to import: /opt/airflow/dags/twitter_love_dag.py
Traceback (most recent call last):
  File "/home/airflow/.local/lib/python3.10/site-packages/airflow/models/dagbag.py", line 346, in parse
    loader.exec_module(new_module)
  File "<frozen importlib._bootstrap_external>", line 883, in exec_module
  File "<frozen importlib._bootstrap>", line 241, in _call_with_frames_removed
  File "/opt/airflow/dags/twitter_love_dag.py", line 15, in <module>
    with open(CREDENTIALS_PATH) as f:
FileNotFoundError: [Errno 2] No such file or directory: '/opt/airflow/data/twitter_api.json'
[2025-08-11T10:06:50.858+0000] {processor.py:842} WARNING - No viable dags retrieved from /opt/airflow/dags/twitter_love_dag.py
[2025-08-11T10:06:50.885+0000] {processor.py:183} INFO - Processing /opt/airflow/dags/twitter_love_dag.py took 0.475 seconds
[2025-08-11T10:07:22.475+0000] {processor.py:161} INFO - Started process (PID=447) to work on /opt/airflow/dags/twitter_love_dag.py
[2025-08-11T10:07:22.476+0000] {processor.py:830} INFO - Processing file /opt/airflow/dags/twitter_love_dag.py for tasks to queue
[2025-08-11T10:07:22.477+0000] {logging_mixin.py:188} INFO - [2025-08-11T10:07:22.477+0000] {dagbag.py:540} INFO - Filling up the DagBag from /opt/airflow/dags/twitter_love_dag.py
[2025-08-11T10:07:22.874+0000] {logging_mixin.py:188} INFO - [2025-08-11T10:07:22.867+0000] {dagbag.py:350} ERROR - Failed to import: /opt/airflow/dags/twitter_love_dag.py
Traceback (most recent call last):
  File "/home/airflow/.local/lib/python3.10/site-packages/airflow/models/dagbag.py", line 346, in parse
    loader.exec_module(new_module)
  File "<frozen importlib._bootstrap_external>", line 883, in exec_module
  File "<frozen importlib._bootstrap>", line 241, in _call_with_frames_removed
  File "/opt/airflow/dags/twitter_love_dag.py", line 15, in <module>
    with open(CREDENTIALS_PATH) as f:
FileNotFoundError: [Errno 2] No such file or directory: '/opt/airflow/data/twitter_api.json'
[2025-08-11T10:07:22.876+0000] {processor.py:842} WARNING - No viable dags retrieved from /opt/airflow/dags/twitter_love_dag.py
[2025-08-11T10:07:22.893+0000] {processor.py:183} INFO - Processing /opt/airflow/dags/twitter_love_dag.py took 0.423 seconds
[2025-08-11T10:07:53.800+0000] {processor.py:161} INFO - Started process (PID=453) to work on /opt/airflow/dags/twitter_love_dag.py
[2025-08-11T10:07:53.801+0000] {processor.py:830} INFO - Processing file /opt/airflow/dags/twitter_love_dag.py for tasks to queue
[2025-08-11T10:07:53.803+0000] {logging_mixin.py:188} INFO - [2025-08-11T10:07:53.803+0000] {dagbag.py:540} INFO - Filling up the DagBag from /opt/airflow/dags/twitter_love_dag.py
[2025-08-11T10:07:54.241+0000] {logging_mixin.py:188} INFO - [2025-08-11T10:07:54.233+0000] {dagbag.py:350} ERROR - Failed to import: /opt/airflow/dags/twitter_love_dag.py
Traceback (most recent call last):
  File "/home/airflow/.local/lib/python3.10/site-packages/airflow/models/dagbag.py", line 346, in parse
    loader.exec_module(new_module)
  File "<frozen importlib._bootstrap_external>", line 883, in exec_module
  File "<frozen importlib._bootstrap>", line 241, in _call_with_frames_removed
  File "/opt/airflow/dags/twitter_love_dag.py", line 15, in <module>
    with open(CREDENTIALS_PATH) as f:
FileNotFoundError: [Errno 2] No such file or directory: '/opt/airflow/data/twitter_api.json'
[2025-08-11T10:07:54.244+0000] {processor.py:842} WARNING - No viable dags retrieved from /opt/airflow/dags/twitter_love_dag.py
[2025-08-11T10:07:54.262+0000] {processor.py:183} INFO - Processing /opt/airflow/dags/twitter_love_dag.py took 0.468 seconds
[2025-08-11T10:08:24.793+0000] {processor.py:161} INFO - Started process (PID=459) to work on /opt/airflow/dags/twitter_love_dag.py
[2025-08-11T10:08:24.795+0000] {processor.py:830} INFO - Processing file /opt/airflow/dags/twitter_love_dag.py for tasks to queue
[2025-08-11T10:08:24.798+0000] {logging_mixin.py:188} INFO - [2025-08-11T10:08:24.798+0000] {dagbag.py:540} INFO - Filling up the DagBag from /opt/airflow/dags/twitter_love_dag.py
[2025-08-11T10:08:25.208+0000] {logging_mixin.py:188} INFO - [2025-08-11T10:08:25.204+0000] {dagbag.py:350} ERROR - Failed to import: /opt/airflow/dags/twitter_love_dag.py
Traceback (most recent call last):
  File "/home/airflow/.local/lib/python3.10/site-packages/airflow/models/dagbag.py", line 346, in parse
    loader.exec_module(new_module)
  File "<frozen importlib._bootstrap_external>", line 883, in exec_module
  File "<frozen importlib._bootstrap>", line 241, in _call_with_frames_removed
  File "/opt/airflow/dags/twitter_love_dag.py", line 15, in <module>
    with open(CREDENTIALS_PATH) as f:
FileNotFoundError: [Errno 2] No such file or directory: '/opt/airflow/data/twitter_api.json'
[2025-08-11T10:08:25.209+0000] {processor.py:842} WARNING - No viable dags retrieved from /opt/airflow/dags/twitter_love_dag.py
[2025-08-11T10:08:25.223+0000] {processor.py:183} INFO - Processing /opt/airflow/dags/twitter_love_dag.py took 0.436 seconds
[2025-08-11T10:08:56.233+0000] {processor.py:161} INFO - Started process (PID=465) to work on /opt/airflow/dags/twitter_love_dag.py
[2025-08-11T10:08:56.234+0000] {processor.py:830} INFO - Processing file /opt/airflow/dags/twitter_love_dag.py for tasks to queue
[2025-08-11T10:08:56.237+0000] {logging_mixin.py:188} INFO - [2025-08-11T10:08:56.237+0000] {dagbag.py:540} INFO - Filling up the DagBag from /opt/airflow/dags/twitter_love_dag.py
[2025-08-11T10:08:56.633+0000] {logging_mixin.py:188} INFO - [2025-08-11T10:08:56.627+0000] {dagbag.py:350} ERROR - Failed to import: /opt/airflow/dags/twitter_love_dag.py
Traceback (most recent call last):
  File "/home/airflow/.local/lib/python3.10/site-packages/airflow/models/dagbag.py", line 346, in parse
    loader.exec_module(new_module)
  File "<frozen importlib._bootstrap_external>", line 883, in exec_module
  File "<frozen importlib._bootstrap>", line 241, in _call_with_frames_removed
  File "/opt/airflow/dags/twitter_love_dag.py", line 15, in <module>
    with open(CREDENTIALS_PATH) as f:
FileNotFoundError: [Errno 2] No such file or directory: '/opt/airflow/data/twitter_api.json'
[2025-08-11T10:08:56.634+0000] {processor.py:842} WARNING - No viable dags retrieved from /opt/airflow/dags/twitter_love_dag.py
[2025-08-11T10:08:56.647+0000] {processor.py:183} INFO - Processing /opt/airflow/dags/twitter_love_dag.py took 0.419 seconds
[2025-08-11T10:09:27.909+0000] {processor.py:161} INFO - Started process (PID=471) to work on /opt/airflow/dags/twitter_love_dag.py
[2025-08-11T10:09:27.910+0000] {processor.py:830} INFO - Processing file /opt/airflow/dags/twitter_love_dag.py for tasks to queue
[2025-08-11T10:09:27.912+0000] {logging_mixin.py:188} INFO - [2025-08-11T10:09:27.911+0000] {dagbag.py:540} INFO - Filling up the DagBag from /opt/airflow/dags/twitter_love_dag.py
[2025-08-11T10:09:28.364+0000] {logging_mixin.py:188} INFO - [2025-08-11T10:09:28.358+0000] {dagbag.py:350} ERROR - Failed to import: /opt/airflow/dags/twitter_love_dag.py
Traceback (most recent call last):
  File "/home/airflow/.local/lib/python3.10/site-packages/airflow/models/dagbag.py", line 346, in parse
    loader.exec_module(new_module)
  File "<frozen importlib._bootstrap_external>", line 883, in exec_module
  File "<frozen importlib._bootstrap>", line 241, in _call_with_frames_removed
  File "/opt/airflow/dags/twitter_love_dag.py", line 15, in <module>
    with open(CREDENTIALS_PATH) as f:
FileNotFoundError: [Errno 2] No such file or directory: '/opt/airflow/data/twitter_api.json'
[2025-08-11T10:09:28.365+0000] {processor.py:842} WARNING - No viable dags retrieved from /opt/airflow/dags/twitter_love_dag.py
[2025-08-11T10:09:28.377+0000] {processor.py:183} INFO - Processing /opt/airflow/dags/twitter_love_dag.py took 0.473 seconds
[2025-08-11T10:09:59.037+0000] {processor.py:161} INFO - Started process (PID=477) to work on /opt/airflow/dags/twitter_love_dag.py
[2025-08-11T10:09:59.038+0000] {processor.py:830} INFO - Processing file /opt/airflow/dags/twitter_love_dag.py for tasks to queue
[2025-08-11T10:09:59.040+0000] {logging_mixin.py:188} INFO - [2025-08-11T10:09:59.040+0000] {dagbag.py:540} INFO - Filling up the DagBag from /opt/airflow/dags/twitter_love_dag.py
[2025-08-11T10:09:59.441+0000] {logging_mixin.py:188} INFO - [2025-08-11T10:09:59.437+0000] {dagbag.py:350} ERROR - Failed to import: /opt/airflow/dags/twitter_love_dag.py
Traceback (most recent call last):
  File "/home/airflow/.local/lib/python3.10/site-packages/airflow/models/dagbag.py", line 346, in parse
    loader.exec_module(new_module)
  File "<frozen importlib._bootstrap_external>", line 883, in exec_module
  File "<frozen importlib._bootstrap>", line 241, in _call_with_frames_removed
  File "/opt/airflow/dags/twitter_love_dag.py", line 15, in <module>
    with open(CREDENTIALS_PATH) as f:
FileNotFoundError: [Errno 2] No such file or directory: '/opt/airflow/data/twitter_api.json'
[2025-08-11T10:09:59.442+0000] {processor.py:842} WARNING - No viable dags retrieved from /opt/airflow/dags/twitter_love_dag.py
[2025-08-11T10:09:59.455+0000] {processor.py:183} INFO - Processing /opt/airflow/dags/twitter_love_dag.py took 0.423 seconds
[2025-08-11T10:10:30.195+0000] {processor.py:161} INFO - Started process (PID=483) to work on /opt/airflow/dags/twitter_love_dag.py
[2025-08-11T10:10:30.196+0000] {processor.py:830} INFO - Processing file /opt/airflow/dags/twitter_love_dag.py for tasks to queue
[2025-08-11T10:10:30.197+0000] {logging_mixin.py:188} INFO - [2025-08-11T10:10:30.197+0000] {dagbag.py:540} INFO - Filling up the DagBag from /opt/airflow/dags/twitter_love_dag.py
[2025-08-11T10:10:30.965+0000] {logging_mixin.py:188} INFO - [2025-08-11T10:10:30.959+0000] {dagbag.py:350} ERROR - Failed to import: /opt/airflow/dags/twitter_love_dag.py
Traceback (most recent call last):
  File "/home/airflow/.local/lib/python3.10/site-packages/airflow/models/dagbag.py", line 346, in parse
    loader.exec_module(new_module)
  File "<frozen importlib._bootstrap_external>", line 883, in exec_module
  File "<frozen importlib._bootstrap>", line 241, in _call_with_frames_removed
  File "/opt/airflow/dags/twitter_love_dag.py", line 15, in <module>
    with open(CREDENTIALS_PATH) as f:
FileNotFoundError: [Errno 2] No such file or directory: '/opt/airflow/data/twitter_api.json'
[2025-08-11T10:10:30.968+0000] {processor.py:842} WARNING - No viable dags retrieved from /opt/airflow/dags/twitter_love_dag.py
[2025-08-11T10:10:30.982+0000] {processor.py:183} INFO - Processing /opt/airflow/dags/twitter_love_dag.py took 0.793 seconds
[2025-08-11T10:11:01.587+0000] {processor.py:161} INFO - Started process (PID=489) to work on /opt/airflow/dags/twitter_love_dag.py
[2025-08-11T10:11:01.588+0000] {processor.py:830} INFO - Processing file /opt/airflow/dags/twitter_love_dag.py for tasks to queue
[2025-08-11T10:11:01.590+0000] {logging_mixin.py:188} INFO - [2025-08-11T10:11:01.589+0000] {dagbag.py:540} INFO - Filling up the DagBag from /opt/airflow/dags/twitter_love_dag.py
[2025-08-11T10:11:01.969+0000] {logging_mixin.py:188} INFO - [2025-08-11T10:11:01.965+0000] {dagbag.py:350} ERROR - Failed to import: /opt/airflow/dags/twitter_love_dag.py
Traceback (most recent call last):
  File "/home/airflow/.local/lib/python3.10/site-packages/airflow/models/dagbag.py", line 346, in parse
    loader.exec_module(new_module)
  File "<frozen importlib._bootstrap_external>", line 883, in exec_module
  File "<frozen importlib._bootstrap>", line 241, in _call_with_frames_removed
  File "/opt/airflow/dags/twitter_love_dag.py", line 15, in <module>
    with open(CREDENTIALS_PATH) as f:
FileNotFoundError: [Errno 2] No such file or directory: '/opt/airflow/data/twitter_api.json'
[2025-08-11T10:11:01.969+0000] {processor.py:842} WARNING - No viable dags retrieved from /opt/airflow/dags/twitter_love_dag.py
[2025-08-11T10:11:01.982+0000] {processor.py:183} INFO - Processing /opt/airflow/dags/twitter_love_dag.py took 0.400 seconds
[2025-08-11T10:11:33.392+0000] {processor.py:161} INFO - Started process (PID=495) to work on /opt/airflow/dags/twitter_love_dag.py
[2025-08-11T10:11:33.393+0000] {processor.py:830} INFO - Processing file /opt/airflow/dags/twitter_love_dag.py for tasks to queue
[2025-08-11T10:11:33.395+0000] {logging_mixin.py:188} INFO - [2025-08-11T10:11:33.394+0000] {dagbag.py:540} INFO - Filling up the DagBag from /opt/airflow/dags/twitter_love_dag.py
[2025-08-11T10:11:33.773+0000] {logging_mixin.py:188} INFO - [2025-08-11T10:11:33.759+0000] {dagbag.py:350} ERROR - Failed to import: /opt/airflow/dags/twitter_love_dag.py
Traceback (most recent call last):
  File "/home/airflow/.local/lib/python3.10/site-packages/airflow/models/dagbag.py", line 346, in parse
    loader.exec_module(new_module)
  File "<frozen importlib._bootstrap_external>", line 883, in exec_module
  File "<frozen importlib._bootstrap>", line 241, in _call_with_frames_removed
  File "/opt/airflow/dags/twitter_love_dag.py", line 15, in <module>
    with open(CREDENTIALS_PATH) as f:
FileNotFoundError: [Errno 2] No such file or directory: '/opt/airflow/data/twitter_api.json'
[2025-08-11T10:11:33.775+0000] {processor.py:842} WARNING - No viable dags retrieved from /opt/airflow/dags/twitter_love_dag.py
[2025-08-11T10:11:33.791+0000] {processor.py:183} INFO - Processing /opt/airflow/dags/twitter_love_dag.py took 0.405 seconds
[2025-08-11T10:12:05.240+0000] {processor.py:161} INFO - Started process (PID=501) to work on /opt/airflow/dags/twitter_love_dag.py
[2025-08-11T10:12:05.241+0000] {processor.py:830} INFO - Processing file /opt/airflow/dags/twitter_love_dag.py for tasks to queue
[2025-08-11T10:12:05.243+0000] {logging_mixin.py:188} INFO - [2025-08-11T10:12:05.243+0000] {dagbag.py:540} INFO - Filling up the DagBag from /opt/airflow/dags/twitter_love_dag.py
[2025-08-11T10:12:05.619+0000] {logging_mixin.py:188} INFO - [2025-08-11T10:12:05.611+0000] {dagbag.py:350} ERROR - Failed to import: /opt/airflow/dags/twitter_love_dag.py
Traceback (most recent call last):
  File "/home/airflow/.local/lib/python3.10/site-packages/airflow/models/dagbag.py", line 346, in parse
    loader.exec_module(new_module)
  File "<frozen importlib._bootstrap_external>", line 883, in exec_module
  File "<frozen importlib._bootstrap>", line 241, in _call_with_frames_removed
  File "/opt/airflow/dags/twitter_love_dag.py", line 15, in <module>
    with open(CREDENTIALS_PATH) as f:
FileNotFoundError: [Errno 2] No such file or directory: '/opt/airflow/data/twitter_api.json'
[2025-08-11T10:12:05.621+0000] {processor.py:842} WARNING - No viable dags retrieved from /opt/airflow/dags/twitter_love_dag.py
[2025-08-11T10:12:05.635+0000] {processor.py:183} INFO - Processing /opt/airflow/dags/twitter_love_dag.py took 0.403 seconds
[2025-08-11T10:12:36.337+0000] {processor.py:161} INFO - Started process (PID=507) to work on /opt/airflow/dags/twitter_love_dag.py
[2025-08-11T10:12:36.338+0000] {processor.py:830} INFO - Processing file /opt/airflow/dags/twitter_love_dag.py for tasks to queue
[2025-08-11T10:12:36.340+0000] {logging_mixin.py:188} INFO - [2025-08-11T10:12:36.339+0000] {dagbag.py:540} INFO - Filling up the DagBag from /opt/airflow/dags/twitter_love_dag.py
[2025-08-11T10:12:36.723+0000] {logging_mixin.py:188} INFO - [2025-08-11T10:12:36.717+0000] {dagbag.py:350} ERROR - Failed to import: /opt/airflow/dags/twitter_love_dag.py
Traceback (most recent call last):
  File "/home/airflow/.local/lib/python3.10/site-packages/airflow/models/dagbag.py", line 346, in parse
    loader.exec_module(new_module)
  File "<frozen importlib._bootstrap_external>", line 883, in exec_module
  File "<frozen importlib._bootstrap>", line 241, in _call_with_frames_removed
  File "/opt/airflow/dags/twitter_love_dag.py", line 15, in <module>
    with open(CREDENTIALS_PATH) as f:
FileNotFoundError: [Errno 2] No such file or directory: '/opt/airflow/data/twitter_api.json'
[2025-08-11T10:12:36.726+0000] {processor.py:842} WARNING - No viable dags retrieved from /opt/airflow/dags/twitter_love_dag.py
[2025-08-11T10:12:36.738+0000] {processor.py:183} INFO - Processing /opt/airflow/dags/twitter_love_dag.py took 0.406 seconds
[2025-08-11T10:13:07.812+0000] {processor.py:161} INFO - Started process (PID=513) to work on /opt/airflow/dags/twitter_love_dag.py
[2025-08-11T10:13:07.813+0000] {processor.py:830} INFO - Processing file /opt/airflow/dags/twitter_love_dag.py for tasks to queue
[2025-08-11T10:13:07.814+0000] {logging_mixin.py:188} INFO - [2025-08-11T10:13:07.814+0000] {dagbag.py:540} INFO - Filling up the DagBag from /opt/airflow/dags/twitter_love_dag.py
[2025-08-11T10:13:08.175+0000] {logging_mixin.py:188} INFO - [2025-08-11T10:13:08.170+0000] {dagbag.py:350} ERROR - Failed to import: /opt/airflow/dags/twitter_love_dag.py
Traceback (most recent call last):
  File "/home/airflow/.local/lib/python3.10/site-packages/airflow/models/dagbag.py", line 346, in parse
    loader.exec_module(new_module)
  File "<frozen importlib._bootstrap_external>", line 883, in exec_module
  File "<frozen importlib._bootstrap>", line 241, in _call_with_frames_removed
  File "/opt/airflow/dags/twitter_love_dag.py", line 15, in <module>
    with open(CREDENTIALS_PATH) as f:
FileNotFoundError: [Errno 2] No such file or directory: '/opt/airflow/data/twitter_api.json'
[2025-08-11T10:13:08.176+0000] {processor.py:842} WARNING - No viable dags retrieved from /opt/airflow/dags/twitter_love_dag.py
[2025-08-11T10:13:08.190+0000] {processor.py:183} INFO - Processing /opt/airflow/dags/twitter_love_dag.py took 0.384 seconds
[2025-08-11T10:13:38.994+0000] {processor.py:161} INFO - Started process (PID=519) to work on /opt/airflow/dags/twitter_love_dag.py
[2025-08-11T10:13:38.995+0000] {processor.py:830} INFO - Processing file /opt/airflow/dags/twitter_love_dag.py for tasks to queue
[2025-08-11T10:13:38.997+0000] {logging_mixin.py:188} INFO - [2025-08-11T10:13:38.997+0000] {dagbag.py:540} INFO - Filling up the DagBag from /opt/airflow/dags/twitter_love_dag.py
[2025-08-11T10:13:39.371+0000] {logging_mixin.py:188} INFO - [2025-08-11T10:13:39.367+0000] {dagbag.py:350} ERROR - Failed to import: /opt/airflow/dags/twitter_love_dag.py
Traceback (most recent call last):
  File "/home/airflow/.local/lib/python3.10/site-packages/airflow/models/dagbag.py", line 346, in parse
    loader.exec_module(new_module)
  File "<frozen importlib._bootstrap_external>", line 883, in exec_module
  File "<frozen importlib._bootstrap>", line 241, in _call_with_frames_removed
  File "/opt/airflow/dags/twitter_love_dag.py", line 15, in <module>
    with open(CREDENTIALS_PATH) as f:
FileNotFoundError: [Errno 2] No such file or directory: '/opt/airflow/data/twitter_api.json'
[2025-08-11T10:13:39.373+0000] {processor.py:842} WARNING - No viable dags retrieved from /opt/airflow/dags/twitter_love_dag.py
[2025-08-11T10:13:39.387+0000] {processor.py:183} INFO - Processing /opt/airflow/dags/twitter_love_dag.py took 0.398 seconds
[2025-08-11T10:14:10.394+0000] {processor.py:161} INFO - Started process (PID=525) to work on /opt/airflow/dags/twitter_love_dag.py
[2025-08-11T10:14:10.396+0000] {processor.py:830} INFO - Processing file /opt/airflow/dags/twitter_love_dag.py for tasks to queue
[2025-08-11T10:14:10.398+0000] {logging_mixin.py:188} INFO - [2025-08-11T10:14:10.397+0000] {dagbag.py:540} INFO - Filling up the DagBag from /opt/airflow/dags/twitter_love_dag.py
[2025-08-11T10:14:10.848+0000] {logging_mixin.py:188} INFO - [2025-08-11T10:14:10.841+0000] {dagbag.py:350} ERROR - Failed to import: /opt/airflow/dags/twitter_love_dag.py
Traceback (most recent call last):
  File "/home/airflow/.local/lib/python3.10/site-packages/airflow/models/dagbag.py", line 346, in parse
    loader.exec_module(new_module)
  File "<frozen importlib._bootstrap_external>", line 883, in exec_module
  File "<frozen importlib._bootstrap>", line 241, in _call_with_frames_removed
  File "/opt/airflow/dags/twitter_love_dag.py", line 15, in <module>
    with open(CREDENTIALS_PATH) as f:
FileNotFoundError: [Errno 2] No such file or directory: '/opt/airflow/data/twitter_api.json'
[2025-08-11T10:14:10.850+0000] {processor.py:842} WARNING - No viable dags retrieved from /opt/airflow/dags/twitter_love_dag.py
[2025-08-11T10:14:10.866+0000] {processor.py:183} INFO - Processing /opt/airflow/dags/twitter_love_dag.py took 0.477 seconds
[2025-08-11T10:14:42.689+0000] {processor.py:161} INFO - Started process (PID=531) to work on /opt/airflow/dags/twitter_love_dag.py
[2025-08-11T10:14:42.691+0000] {processor.py:830} INFO - Processing file /opt/airflow/dags/twitter_love_dag.py for tasks to queue
[2025-08-11T10:14:42.693+0000] {logging_mixin.py:188} INFO - [2025-08-11T10:14:42.692+0000] {dagbag.py:540} INFO - Filling up the DagBag from /opt/airflow/dags/twitter_love_dag.py
[2025-08-11T10:14:43.096+0000] {logging_mixin.py:188} INFO - [2025-08-11T10:14:43.092+0000] {dagbag.py:350} ERROR - Failed to import: /opt/airflow/dags/twitter_love_dag.py
Traceback (most recent call last):
  File "/home/airflow/.local/lib/python3.10/site-packages/airflow/models/dagbag.py", line 346, in parse
    loader.exec_module(new_module)
  File "<frozen importlib._bootstrap_external>", line 883, in exec_module
  File "<frozen importlib._bootstrap>", line 241, in _call_with_frames_removed
  File "/opt/airflow/dags/twitter_love_dag.py", line 15, in <module>
    with open(CREDENTIALS_PATH) as f:
FileNotFoundError: [Errno 2] No such file or directory: '/opt/airflow/data/twitter_api.json'
[2025-08-11T10:14:43.097+0000] {processor.py:842} WARNING - No viable dags retrieved from /opt/airflow/dags/twitter_love_dag.py
[2025-08-11T10:14:43.109+0000] {processor.py:183} INFO - Processing /opt/airflow/dags/twitter_love_dag.py took 0.425 seconds
[2025-08-11T11:33:23.506+0000] {processor.py:161} INFO - Started process (PID=37) to work on /opt/airflow/dags/twitter_love_dag.py
[2025-08-11T11:33:23.511+0000] {processor.py:830} INFO - Processing file /opt/airflow/dags/twitter_love_dag.py for tasks to queue
[2025-08-11T11:33:23.522+0000] {logging_mixin.py:188} INFO - [2025-08-11T11:33:23.521+0000] {dagbag.py:540} INFO - Filling up the DagBag from /opt/airflow/dags/twitter_love_dag.py
[2025-08-11T11:33:25.304+0000] {logging_mixin.py:188} INFO - [2025-08-11T11:33:25.281+0000] {dagbag.py:350} ERROR - Failed to import: /opt/airflow/dags/twitter_love_dag.py
Traceback (most recent call last):
  File "/home/airflow/.local/lib/python3.10/site-packages/airflow/models/dagbag.py", line 346, in parse
    loader.exec_module(new_module)
  File "<frozen importlib._bootstrap_external>", line 883, in exec_module
  File "<frozen importlib._bootstrap>", line 241, in _call_with_frames_removed
  File "/opt/airflow/dags/twitter_love_dag.py", line 15, in <module>
    with open(CREDENTIALS_PATH) as f:
FileNotFoundError: [Errno 2] No such file or directory: '/opt/airflow/data/twitter_api.json'
[2025-08-11T11:33:25.307+0000] {processor.py:842} WARNING - No viable dags retrieved from /opt/airflow/dags/twitter_love_dag.py
[2025-08-11T11:33:25.431+0000] {processor.py:183} INFO - Processing /opt/airflow/dags/twitter_love_dag.py took 1.953 seconds
[2025-08-11T11:33:55.701+0000] {processor.py:161} INFO - Started process (PID=41) to work on /opt/airflow/dags/twitter_love_dag.py
[2025-08-11T11:33:55.702+0000] {processor.py:830} INFO - Processing file /opt/airflow/dags/twitter_love_dag.py for tasks to queue
[2025-08-11T11:33:55.704+0000] {logging_mixin.py:188} INFO - [2025-08-11T11:33:55.704+0000] {dagbag.py:540} INFO - Filling up the DagBag from /opt/airflow/dags/twitter_love_dag.py
[2025-08-11T11:34:00.660+0000] {logging_mixin.py:188} INFO - [2025-08-11T11:34:00.654+0000] {dagbag.py:350} ERROR - Failed to import: /opt/airflow/dags/twitter_love_dag.py
Traceback (most recent call last):
  File "/home/airflow/.local/lib/python3.10/site-packages/airflow/models/dagbag.py", line 346, in parse
    loader.exec_module(new_module)
  File "<frozen importlib._bootstrap_external>", line 883, in exec_module
  File "<frozen importlib._bootstrap>", line 241, in _call_with_frames_removed
  File "/opt/airflow/dags/twitter_love_dag.py", line 15, in <module>
    with open(CREDENTIALS_PATH) as f:
FileNotFoundError: [Errno 2] No such file or directory: '/opt/airflow/data/twitter_api.json'
[2025-08-11T11:34:00.661+0000] {processor.py:842} WARNING - No viable dags retrieved from /opt/airflow/dags/twitter_love_dag.py
[2025-08-11T11:34:00.722+0000] {processor.py:183} INFO - Processing /opt/airflow/dags/twitter_love_dag.py took 5.033 seconds
[2025-08-11T11:34:31.153+0000] {processor.py:161} INFO - Started process (PID=47) to work on /opt/airflow/dags/twitter_love_dag.py
[2025-08-11T11:34:31.154+0000] {processor.py:830} INFO - Processing file /opt/airflow/dags/twitter_love_dag.py for tasks to queue
[2025-08-11T11:34:31.157+0000] {logging_mixin.py:188} INFO - [2025-08-11T11:34:31.157+0000] {dagbag.py:540} INFO - Filling up the DagBag from /opt/airflow/dags/twitter_love_dag.py
[2025-08-11T11:34:32.057+0000] {logging_mixin.py:188} INFO - [2025-08-11T11:34:32.049+0000] {dagbag.py:350} ERROR - Failed to import: /opt/airflow/dags/twitter_love_dag.py
Traceback (most recent call last):
  File "/home/airflow/.local/lib/python3.10/site-packages/airflow/models/dagbag.py", line 346, in parse
    loader.exec_module(new_module)
  File "<frozen importlib._bootstrap_external>", line 883, in exec_module
  File "<frozen importlib._bootstrap>", line 241, in _call_with_frames_removed
  File "/opt/airflow/dags/twitter_love_dag.py", line 15, in <module>
    with open(CREDENTIALS_PATH) as f:
FileNotFoundError: [Errno 2] No such file or directory: '/opt/airflow/data/twitter_api.json'
[2025-08-11T11:34:32.059+0000] {processor.py:842} WARNING - No viable dags retrieved from /opt/airflow/dags/twitter_love_dag.py
[2025-08-11T11:34:32.124+0000] {processor.py:183} INFO - Processing /opt/airflow/dags/twitter_love_dag.py took 0.980 seconds
[2025-08-11T11:35:03.189+0000] {processor.py:161} INFO - Started process (PID=53) to work on /opt/airflow/dags/twitter_love_dag.py
[2025-08-11T11:35:03.193+0000] {processor.py:830} INFO - Processing file /opt/airflow/dags/twitter_love_dag.py for tasks to queue
[2025-08-11T11:35:03.220+0000] {logging_mixin.py:188} INFO - [2025-08-11T11:35:03.220+0000] {dagbag.py:540} INFO - Filling up the DagBag from /opt/airflow/dags/twitter_love_dag.py
[2025-08-11T11:35:05.524+0000] {logging_mixin.py:188} INFO - [2025-08-11T11:35:05.481+0000] {dagbag.py:350} ERROR - Failed to import: /opt/airflow/dags/twitter_love_dag.py
Traceback (most recent call last):
  File "/home/airflow/.local/lib/python3.10/site-packages/airflow/models/dagbag.py", line 346, in parse
    loader.exec_module(new_module)
  File "<frozen importlib._bootstrap_external>", line 883, in exec_module
  File "<frozen importlib._bootstrap>", line 241, in _call_with_frames_removed
  File "/opt/airflow/dags/twitter_love_dag.py", line 15, in <module>
    with open(CREDENTIALS_PATH) as f:
FileNotFoundError: [Errno 2] No such file or directory: '/opt/airflow/data/twitter_api.json'
[2025-08-11T11:35:05.544+0000] {processor.py:842} WARNING - No viable dags retrieved from /opt/airflow/dags/twitter_love_dag.py
[2025-08-11T11:35:05.671+0000] {processor.py:183} INFO - Processing /opt/airflow/dags/twitter_love_dag.py took 2.500 seconds
[2025-08-11T11:35:36.071+0000] {processor.py:161} INFO - Started process (PID=59) to work on /opt/airflow/dags/twitter_love_dag.py
[2025-08-11T11:35:36.072+0000] {processor.py:830} INFO - Processing file /opt/airflow/dags/twitter_love_dag.py for tasks to queue
[2025-08-11T11:35:36.074+0000] {logging_mixin.py:188} INFO - [2025-08-11T11:35:36.073+0000] {dagbag.py:540} INFO - Filling up the DagBag from /opt/airflow/dags/twitter_love_dag.py
[2025-08-11T11:35:38.025+0000] {logging_mixin.py:188} INFO - [2025-08-11T11:35:38.016+0000] {dagbag.py:350} ERROR - Failed to import: /opt/airflow/dags/twitter_love_dag.py
Traceback (most recent call last):
  File "/home/airflow/.local/lib/python3.10/site-packages/airflow/models/dagbag.py", line 346, in parse
    loader.exec_module(new_module)
  File "<frozen importlib._bootstrap_external>", line 883, in exec_module
  File "<frozen importlib._bootstrap>", line 241, in _call_with_frames_removed
  File "/opt/airflow/dags/twitter_love_dag.py", line 15, in <module>
    with open(CREDENTIALS_PATH) as f:
FileNotFoundError: [Errno 2] No such file or directory: '/opt/airflow/data/twitter_api.json'
[2025-08-11T11:35:38.027+0000] {processor.py:842} WARNING - No viable dags retrieved from /opt/airflow/dags/twitter_love_dag.py
[2025-08-11T11:35:38.332+0000] {processor.py:183} INFO - Processing /opt/airflow/dags/twitter_love_dag.py took 2.267 seconds
[2025-08-11T11:36:09.070+0000] {processor.py:161} INFO - Started process (PID=65) to work on /opt/airflow/dags/twitter_love_dag.py
[2025-08-11T11:36:09.071+0000] {processor.py:830} INFO - Processing file /opt/airflow/dags/twitter_love_dag.py for tasks to queue
[2025-08-11T11:36:09.073+0000] {logging_mixin.py:188} INFO - [2025-08-11T11:36:09.073+0000] {dagbag.py:540} INFO - Filling up the DagBag from /opt/airflow/dags/twitter_love_dag.py
[2025-08-11T11:36:09.594+0000] {logging_mixin.py:188} INFO - [2025-08-11T11:36:09.589+0000] {dagbag.py:350} ERROR - Failed to import: /opt/airflow/dags/twitter_love_dag.py
Traceback (most recent call last):
  File "/home/airflow/.local/lib/python3.10/site-packages/airflow/models/dagbag.py", line 346, in parse
    loader.exec_module(new_module)
  File "<frozen importlib._bootstrap_external>", line 883, in exec_module
  File "<frozen importlib._bootstrap>", line 241, in _call_with_frames_removed
  File "/opt/airflow/dags/twitter_love_dag.py", line 15, in <module>
    with open(CREDENTIALS_PATH) as f:
FileNotFoundError: [Errno 2] No such file or directory: '/opt/airflow/data/twitter_api.json'
[2025-08-11T11:36:09.595+0000] {processor.py:842} WARNING - No viable dags retrieved from /opt/airflow/dags/twitter_love_dag.py
[2025-08-11T11:36:09.697+0000] {processor.py:183} INFO - Processing /opt/airflow/dags/twitter_love_dag.py took 0.636 seconds
[2025-08-11T11:36:40.032+0000] {processor.py:161} INFO - Started process (PID=71) to work on /opt/airflow/dags/twitter_love_dag.py
[2025-08-11T11:36:40.033+0000] {processor.py:830} INFO - Processing file /opt/airflow/dags/twitter_love_dag.py for tasks to queue
[2025-08-11T11:36:40.035+0000] {logging_mixin.py:188} INFO - [2025-08-11T11:36:40.035+0000] {dagbag.py:540} INFO - Filling up the DagBag from /opt/airflow/dags/twitter_love_dag.py
[2025-08-11T11:36:40.602+0000] {logging_mixin.py:188} INFO - [2025-08-11T11:36:40.596+0000] {dagbag.py:350} ERROR - Failed to import: /opt/airflow/dags/twitter_love_dag.py
Traceback (most recent call last):
  File "/home/airflow/.local/lib/python3.10/site-packages/airflow/models/dagbag.py", line 346, in parse
    loader.exec_module(new_module)
  File "<frozen importlib._bootstrap_external>", line 883, in exec_module
  File "<frozen importlib._bootstrap>", line 241, in _call_with_frames_removed
  File "/opt/airflow/dags/twitter_love_dag.py", line 15, in <module>
    with open(CREDENTIALS_PATH) as f:
FileNotFoundError: [Errno 2] No such file or directory: '/opt/airflow/data/twitter_api.json'
[2025-08-11T11:36:40.603+0000] {processor.py:842} WARNING - No viable dags retrieved from /opt/airflow/dags/twitter_love_dag.py
[2025-08-11T11:36:40.626+0000] {processor.py:183} INFO - Processing /opt/airflow/dags/twitter_love_dag.py took 0.601 seconds
[2025-08-11T11:37:10.804+0000] {processor.py:161} INFO - Started process (PID=77) to work on /opt/airflow/dags/twitter_love_dag.py
[2025-08-11T11:37:10.806+0000] {processor.py:830} INFO - Processing file /opt/airflow/dags/twitter_love_dag.py for tasks to queue
[2025-08-11T11:37:10.807+0000] {logging_mixin.py:188} INFO - [2025-08-11T11:37:10.807+0000] {dagbag.py:540} INFO - Filling up the DagBag from /opt/airflow/dags/twitter_love_dag.py
[2025-08-11T11:37:11.358+0000] {logging_mixin.py:188} INFO - [2025-08-11T11:37:11.350+0000] {dagbag.py:350} ERROR - Failed to import: /opt/airflow/dags/twitter_love_dag.py
Traceback (most recent call last):
  File "/home/airflow/.local/lib/python3.10/site-packages/airflow/models/dagbag.py", line 346, in parse
    loader.exec_module(new_module)
  File "<frozen importlib._bootstrap_external>", line 883, in exec_module
  File "<frozen importlib._bootstrap>", line 241, in _call_with_frames_removed
  File "/opt/airflow/dags/twitter_love_dag.py", line 15, in <module>
    with open(CREDENTIALS_PATH) as f:
FileNotFoundError: [Errno 2] No such file or directory: '/opt/airflow/data/twitter_api.json'
[2025-08-11T11:37:11.361+0000] {processor.py:842} WARNING - No viable dags retrieved from /opt/airflow/dags/twitter_love_dag.py
[2025-08-11T11:37:11.378+0000] {processor.py:183} INFO - Processing /opt/airflow/dags/twitter_love_dag.py took 0.582 seconds
[2025-08-11T11:37:42.018+0000] {processor.py:161} INFO - Started process (PID=83) to work on /opt/airflow/dags/twitter_love_dag.py
[2025-08-11T11:37:42.049+0000] {processor.py:830} INFO - Processing file /opt/airflow/dags/twitter_love_dag.py for tasks to queue
[2025-08-11T11:37:42.054+0000] {logging_mixin.py:188} INFO - [2025-08-11T11:37:42.053+0000] {dagbag.py:540} INFO - Filling up the DagBag from /opt/airflow/dags/twitter_love_dag.py
[2025-08-11T11:37:42.516+0000] {logging_mixin.py:188} INFO - [2025-08-11T11:37:42.499+0000] {dagbag.py:350} ERROR - Failed to import: /opt/airflow/dags/twitter_love_dag.py
Traceback (most recent call last):
  File "/home/airflow/.local/lib/python3.10/site-packages/airflow/models/dagbag.py", line 346, in parse
    loader.exec_module(new_module)
  File "<frozen importlib._bootstrap_external>", line 883, in exec_module
  File "<frozen importlib._bootstrap>", line 241, in _call_with_frames_removed
  File "/opt/airflow/dags/twitter_love_dag.py", line 15, in <module>
    with open(CREDENTIALS_PATH) as f:
FileNotFoundError: [Errno 2] No such file or directory: '/opt/airflow/data/twitter_api.json'
[2025-08-11T11:37:42.521+0000] {processor.py:842} WARNING - No viable dags retrieved from /opt/airflow/dags/twitter_love_dag.py
[2025-08-11T11:37:42.549+0000] {processor.py:183} INFO - Processing /opt/airflow/dags/twitter_love_dag.py took 0.537 seconds
[2025-08-11T11:38:13.322+0000] {processor.py:161} INFO - Started process (PID=89) to work on /opt/airflow/dags/twitter_love_dag.py
[2025-08-11T11:38:13.325+0000] {processor.py:830} INFO - Processing file /opt/airflow/dags/twitter_love_dag.py for tasks to queue
[2025-08-11T11:38:13.330+0000] {logging_mixin.py:188} INFO - [2025-08-11T11:38:13.329+0000] {dagbag.py:540} INFO - Filling up the DagBag from /opt/airflow/dags/twitter_love_dag.py
[2025-08-11T11:38:13.891+0000] {logging_mixin.py:188} INFO - [2025-08-11T11:38:13.776+0000] {dagbag.py:350} ERROR - Failed to import: /opt/airflow/dags/twitter_love_dag.py
Traceback (most recent call last):
  File "/home/airflow/.local/lib/python3.10/site-packages/airflow/models/dagbag.py", line 346, in parse
    loader.exec_module(new_module)
  File "<frozen importlib._bootstrap_external>", line 883, in exec_module
  File "<frozen importlib._bootstrap>", line 241, in _call_with_frames_removed
  File "/opt/airflow/dags/twitter_love_dag.py", line 15, in <module>
    with open(CREDENTIALS_PATH) as f:
FileNotFoundError: [Errno 2] No such file or directory: '/opt/airflow/data/twitter_api.json'
[2025-08-11T11:38:13.911+0000] {processor.py:842} WARNING - No viable dags retrieved from /opt/airflow/dags/twitter_love_dag.py
[2025-08-11T11:38:13.937+0000] {processor.py:183} INFO - Processing /opt/airflow/dags/twitter_love_dag.py took 0.624 seconds
[2025-08-11T11:38:44.293+0000] {processor.py:161} INFO - Started process (PID=95) to work on /opt/airflow/dags/twitter_love_dag.py
[2025-08-11T11:38:44.296+0000] {processor.py:830} INFO - Processing file /opt/airflow/dags/twitter_love_dag.py for tasks to queue
[2025-08-11T11:38:44.300+0000] {logging_mixin.py:188} INFO - [2025-08-11T11:38:44.300+0000] {dagbag.py:540} INFO - Filling up the DagBag from /opt/airflow/dags/twitter_love_dag.py
[2025-08-11T11:38:44.792+0000] {logging_mixin.py:188} INFO - [2025-08-11T11:38:44.787+0000] {dagbag.py:350} ERROR - Failed to import: /opt/airflow/dags/twitter_love_dag.py
Traceback (most recent call last):
  File "/home/airflow/.local/lib/python3.10/site-packages/airflow/models/dagbag.py", line 346, in parse
    loader.exec_module(new_module)
  File "<frozen importlib._bootstrap_external>", line 883, in exec_module
  File "<frozen importlib._bootstrap>", line 241, in _call_with_frames_removed
  File "/opt/airflow/dags/twitter_love_dag.py", line 15, in <module>
    with open(CREDENTIALS_PATH) as f:
FileNotFoundError: [Errno 2] No such file or directory: '/opt/airflow/data/twitter_api.json'
[2025-08-11T11:38:44.793+0000] {processor.py:842} WARNING - No viable dags retrieved from /opt/airflow/dags/twitter_love_dag.py
[2025-08-11T11:38:44.811+0000] {processor.py:183} INFO - Processing /opt/airflow/dags/twitter_love_dag.py took 0.533 seconds
[2025-08-11T11:39:14.981+0000] {processor.py:161} INFO - Started process (PID=101) to work on /opt/airflow/dags/twitter_love_dag.py
[2025-08-11T11:39:14.982+0000] {processor.py:830} INFO - Processing file /opt/airflow/dags/twitter_love_dag.py for tasks to queue
[2025-08-11T11:39:14.984+0000] {logging_mixin.py:188} INFO - [2025-08-11T11:39:14.984+0000] {dagbag.py:540} INFO - Filling up the DagBag from /opt/airflow/dags/twitter_love_dag.py
[2025-08-11T11:39:15.399+0000] {logging_mixin.py:188} INFO - [2025-08-11T11:39:15.394+0000] {dagbag.py:350} ERROR - Failed to import: /opt/airflow/dags/twitter_love_dag.py
Traceback (most recent call last):
  File "/home/airflow/.local/lib/python3.10/site-packages/airflow/models/dagbag.py", line 346, in parse
    loader.exec_module(new_module)
  File "<frozen importlib._bootstrap_external>", line 883, in exec_module
  File "<frozen importlib._bootstrap>", line 241, in _call_with_frames_removed
  File "/opt/airflow/dags/twitter_love_dag.py", line 15, in <module>
    with open(CREDENTIALS_PATH) as f:
FileNotFoundError: [Errno 2] No such file or directory: '/opt/airflow/data/twitter_api.json'
[2025-08-11T11:39:15.401+0000] {processor.py:842} WARNING - No viable dags retrieved from /opt/airflow/dags/twitter_love_dag.py
[2025-08-11T11:39:15.421+0000] {processor.py:183} INFO - Processing /opt/airflow/dags/twitter_love_dag.py took 0.446 seconds
[2025-08-11T11:39:45.958+0000] {processor.py:161} INFO - Started process (PID=107) to work on /opt/airflow/dags/twitter_love_dag.py
[2025-08-11T11:39:45.960+0000] {processor.py:830} INFO - Processing file /opt/airflow/dags/twitter_love_dag.py for tasks to queue
[2025-08-11T11:39:45.963+0000] {logging_mixin.py:188} INFO - [2025-08-11T11:39:45.963+0000] {dagbag.py:540} INFO - Filling up the DagBag from /opt/airflow/dags/twitter_love_dag.py
[2025-08-11T11:39:46.724+0000] {logging_mixin.py:188} INFO - [2025-08-11T11:39:46.513+0000] {dagbag.py:350} ERROR - Failed to import: /opt/airflow/dags/twitter_love_dag.py
Traceback (most recent call last):
  File "/home/airflow/.local/lib/python3.10/site-packages/airflow/models/dagbag.py", line 346, in parse
    loader.exec_module(new_module)
  File "<frozen importlib._bootstrap_external>", line 883, in exec_module
  File "<frozen importlib._bootstrap>", line 241, in _call_with_frames_removed
  File "/opt/airflow/dags/twitter_love_dag.py", line 15, in <module>
    with open(CREDENTIALS_PATH) as f:
FileNotFoundError: [Errno 2] No such file or directory: '/opt/airflow/data/twitter_api.json'
[2025-08-11T11:39:46.761+0000] {processor.py:842} WARNING - No viable dags retrieved from /opt/airflow/dags/twitter_love_dag.py
[2025-08-11T11:39:46.792+0000] {processor.py:183} INFO - Processing /opt/airflow/dags/twitter_love_dag.py took 0.841 seconds
[2025-08-11T11:40:17.528+0000] {processor.py:161} INFO - Started process (PID=113) to work on /opt/airflow/dags/twitter_love_dag.py
[2025-08-11T11:40:17.530+0000] {processor.py:830} INFO - Processing file /opt/airflow/dags/twitter_love_dag.py for tasks to queue
[2025-08-11T11:40:17.538+0000] {logging_mixin.py:188} INFO - [2025-08-11T11:40:17.537+0000] {dagbag.py:540} INFO - Filling up the DagBag from /opt/airflow/dags/twitter_love_dag.py
[2025-08-11T11:40:18.477+0000] {logging_mixin.py:188} INFO - [2025-08-11T11:40:18.386+0000] {dagbag.py:350} ERROR - Failed to import: /opt/airflow/dags/twitter_love_dag.py
Traceback (most recent call last):
  File "/home/airflow/.local/lib/python3.10/site-packages/airflow/models/dagbag.py", line 346, in parse
    loader.exec_module(new_module)
  File "<frozen importlib._bootstrap_external>", line 883, in exec_module
  File "<frozen importlib._bootstrap>", line 241, in _call_with_frames_removed
  File "/opt/airflow/dags/twitter_love_dag.py", line 15, in <module>
    with open(CREDENTIALS_PATH) as f:
FileNotFoundError: [Errno 2] No such file or directory: '/opt/airflow/data/twitter_api.json'
[2025-08-11T11:40:19.285+0000] {processor.py:842} WARNING - No viable dags retrieved from /opt/airflow/dags/twitter_love_dag.py
[2025-08-11T11:40:19.309+0000] {processor.py:183} INFO - Processing /opt/airflow/dags/twitter_love_dag.py took 0.930 seconds
[2025-08-11T11:40:50.638+0000] {processor.py:161} INFO - Started process (PID=119) to work on /opt/airflow/dags/twitter_love_dag.py
[2025-08-11T11:40:50.639+0000] {processor.py:830} INFO - Processing file /opt/airflow/dags/twitter_love_dag.py for tasks to queue
[2025-08-11T11:40:50.641+0000] {logging_mixin.py:188} INFO - [2025-08-11T11:40:50.641+0000] {dagbag.py:540} INFO - Filling up the DagBag from /opt/airflow/dags/twitter_love_dag.py
[2025-08-11T11:40:51.194+0000] {logging_mixin.py:188} INFO - [2025-08-11T11:40:51.174+0000] {dagbag.py:350} ERROR - Failed to import: /opt/airflow/dags/twitter_love_dag.py
Traceback (most recent call last):
  File "/home/airflow/.local/lib/python3.10/site-packages/airflow/models/dagbag.py", line 346, in parse
    loader.exec_module(new_module)
  File "<frozen importlib._bootstrap_external>", line 883, in exec_module
  File "<frozen importlib._bootstrap>", line 241, in _call_with_frames_removed
  File "/opt/airflow/dags/twitter_love_dag.py", line 15, in <module>
    with open(CREDENTIALS_PATH) as f:
FileNotFoundError: [Errno 2] No such file or directory: '/opt/airflow/data/twitter_api.json'
[2025-08-11T11:40:51.197+0000] {processor.py:842} WARNING - No viable dags retrieved from /opt/airflow/dags/twitter_love_dag.py
[2025-08-11T11:40:51.219+0000] {processor.py:183} INFO - Processing /opt/airflow/dags/twitter_love_dag.py took 0.590 seconds
[2025-08-11T11:41:22.462+0000] {processor.py:161} INFO - Started process (PID=125) to work on /opt/airflow/dags/twitter_love_dag.py
[2025-08-11T11:41:22.463+0000] {processor.py:830} INFO - Processing file /opt/airflow/dags/twitter_love_dag.py for tasks to queue
[2025-08-11T11:41:22.465+0000] {logging_mixin.py:188} INFO - [2025-08-11T11:41:22.465+0000] {dagbag.py:540} INFO - Filling up the DagBag from /opt/airflow/dags/twitter_love_dag.py
[2025-08-11T11:41:22.935+0000] {logging_mixin.py:188} INFO - [2025-08-11T11:41:22.915+0000] {dagbag.py:350} ERROR - Failed to import: /opt/airflow/dags/twitter_love_dag.py
Traceback (most recent call last):
  File "/home/airflow/.local/lib/python3.10/site-packages/airflow/models/dagbag.py", line 346, in parse
    loader.exec_module(new_module)
  File "<frozen importlib._bootstrap_external>", line 883, in exec_module
  File "<frozen importlib._bootstrap>", line 241, in _call_with_frames_removed
  File "/opt/airflow/dags/twitter_love_dag.py", line 15, in <module>
    with open(CREDENTIALS_PATH) as f:
FileNotFoundError: [Errno 2] No such file or directory: '/opt/airflow/data/twitter_api.json'
[2025-08-11T11:41:22.936+0000] {processor.py:842} WARNING - No viable dags retrieved from /opt/airflow/dags/twitter_love_dag.py
[2025-08-11T11:41:22.953+0000] {processor.py:183} INFO - Processing /opt/airflow/dags/twitter_love_dag.py took 0.498 seconds
[2025-08-11T11:41:53.485+0000] {processor.py:161} INFO - Started process (PID=131) to work on /opt/airflow/dags/twitter_love_dag.py
[2025-08-11T11:41:53.487+0000] {processor.py:830} INFO - Processing file /opt/airflow/dags/twitter_love_dag.py for tasks to queue
[2025-08-11T11:41:53.489+0000] {logging_mixin.py:188} INFO - [2025-08-11T11:41:53.489+0000] {dagbag.py:540} INFO - Filling up the DagBag from /opt/airflow/dags/twitter_love_dag.py
[2025-08-11T11:41:54.082+0000] {logging_mixin.py:188} INFO - [2025-08-11T11:41:53.980+0000] {dagbag.py:350} ERROR - Failed to import: /opt/airflow/dags/twitter_love_dag.py
Traceback (most recent call last):
  File "/home/airflow/.local/lib/python3.10/site-packages/airflow/models/dagbag.py", line 346, in parse
    loader.exec_module(new_module)
  File "<frozen importlib._bootstrap_external>", line 883, in exec_module
  File "<frozen importlib._bootstrap>", line 241, in _call_with_frames_removed
  File "/opt/airflow/dags/twitter_love_dag.py", line 15, in <module>
    with open(CREDENTIALS_PATH) as f:
FileNotFoundError: [Errno 2] No such file or directory: '/opt/airflow/data/twitter_api.json'
[2025-08-11T11:41:54.086+0000] {processor.py:842} WARNING - No viable dags retrieved from /opt/airflow/dags/twitter_love_dag.py
[2025-08-11T11:41:54.118+0000] {processor.py:183} INFO - Processing /opt/airflow/dags/twitter_love_dag.py took 0.638 seconds
[2025-08-11T11:42:24.839+0000] {processor.py:161} INFO - Started process (PID=137) to work on /opt/airflow/dags/twitter_love_dag.py
[2025-08-11T11:42:24.840+0000] {processor.py:830} INFO - Processing file /opt/airflow/dags/twitter_love_dag.py for tasks to queue
[2025-08-11T11:42:24.841+0000] {logging_mixin.py:188} INFO - [2025-08-11T11:42:24.841+0000] {dagbag.py:540} INFO - Filling up the DagBag from /opt/airflow/dags/twitter_love_dag.py
[2025-08-11T11:42:25.293+0000] {logging_mixin.py:188} INFO - [2025-08-11T11:42:25.288+0000] {dagbag.py:350} ERROR - Failed to import: /opt/airflow/dags/twitter_love_dag.py
Traceback (most recent call last):
  File "/home/airflow/.local/lib/python3.10/site-packages/airflow/models/dagbag.py", line 346, in parse
    loader.exec_module(new_module)
  File "<frozen importlib._bootstrap_external>", line 883, in exec_module
  File "<frozen importlib._bootstrap>", line 241, in _call_with_frames_removed
  File "/opt/airflow/dags/twitter_love_dag.py", line 15, in <module>
    with open(CREDENTIALS_PATH) as f:
FileNotFoundError: [Errno 2] No such file or directory: '/opt/airflow/data/twitter_api.json'
[2025-08-11T11:42:25.294+0000] {processor.py:842} WARNING - No viable dags retrieved from /opt/airflow/dags/twitter_love_dag.py
[2025-08-11T11:42:25.314+0000] {processor.py:183} INFO - Processing /opt/airflow/dags/twitter_love_dag.py took 0.481 seconds
[2025-08-11T11:42:56.267+0000] {processor.py:161} INFO - Started process (PID=143) to work on /opt/airflow/dags/twitter_love_dag.py
[2025-08-11T11:42:56.271+0000] {processor.py:830} INFO - Processing file /opt/airflow/dags/twitter_love_dag.py for tasks to queue
[2025-08-11T11:42:56.274+0000] {logging_mixin.py:188} INFO - [2025-08-11T11:42:56.273+0000] {dagbag.py:540} INFO - Filling up the DagBag from /opt/airflow/dags/twitter_love_dag.py
[2025-08-11T11:42:56.715+0000] {logging_mixin.py:188} INFO - [2025-08-11T11:42:56.699+0000] {dagbag.py:350} ERROR - Failed to import: /opt/airflow/dags/twitter_love_dag.py
Traceback (most recent call last):
  File "/home/airflow/.local/lib/python3.10/site-packages/airflow/models/dagbag.py", line 346, in parse
    loader.exec_module(new_module)
  File "<frozen importlib._bootstrap_external>", line 883, in exec_module
  File "<frozen importlib._bootstrap>", line 241, in _call_with_frames_removed
  File "/opt/airflow/dags/twitter_love_dag.py", line 15, in <module>
    with open(CREDENTIALS_PATH) as f:
FileNotFoundError: [Errno 2] No such file or directory: '/opt/airflow/data/twitter_api.json'
[2025-08-11T11:42:56.725+0000] {processor.py:842} WARNING - No viable dags retrieved from /opt/airflow/dags/twitter_love_dag.py
[2025-08-11T11:42:56.744+0000] {processor.py:183} INFO - Processing /opt/airflow/dags/twitter_love_dag.py took 0.486 seconds
[2025-08-11T11:43:27.849+0000] {processor.py:161} INFO - Started process (PID=149) to work on /opt/airflow/dags/twitter_love_dag.py
[2025-08-11T11:43:27.850+0000] {processor.py:830} INFO - Processing file /opt/airflow/dags/twitter_love_dag.py for tasks to queue
[2025-08-11T11:43:27.852+0000] {logging_mixin.py:188} INFO - [2025-08-11T11:43:27.852+0000] {dagbag.py:540} INFO - Filling up the DagBag from /opt/airflow/dags/twitter_love_dag.py
[2025-08-11T11:43:28.274+0000] {logging_mixin.py:188} INFO - [2025-08-11T11:43:28.269+0000] {dagbag.py:350} ERROR - Failed to import: /opt/airflow/dags/twitter_love_dag.py
Traceback (most recent call last):
  File "/home/airflow/.local/lib/python3.10/site-packages/airflow/models/dagbag.py", line 346, in parse
    loader.exec_module(new_module)
  File "<frozen importlib._bootstrap_external>", line 883, in exec_module
  File "<frozen importlib._bootstrap>", line 241, in _call_with_frames_removed
  File "/opt/airflow/dags/twitter_love_dag.py", line 15, in <module>
    with open(CREDENTIALS_PATH) as f:
FileNotFoundError: [Errno 2] No such file or directory: '/opt/airflow/data/twitter_api.json'
[2025-08-11T11:43:28.275+0000] {processor.py:842} WARNING - No viable dags retrieved from /opt/airflow/dags/twitter_love_dag.py
[2025-08-11T11:43:28.292+0000] {processor.py:183} INFO - Processing /opt/airflow/dags/twitter_love_dag.py took 0.449 seconds
[2025-08-11T11:43:58.401+0000] {processor.py:161} INFO - Started process (PID=155) to work on /opt/airflow/dags/twitter_love_dag.py
[2025-08-11T11:43:58.402+0000] {processor.py:830} INFO - Processing file /opt/airflow/dags/twitter_love_dag.py for tasks to queue
[2025-08-11T11:43:58.403+0000] {logging_mixin.py:188} INFO - [2025-08-11T11:43:58.403+0000] {dagbag.py:540} INFO - Filling up the DagBag from /opt/airflow/dags/twitter_love_dag.py
[2025-08-11T11:43:58.926+0000] {logging_mixin.py:188} INFO - [2025-08-11T11:43:58.904+0000] {dagbag.py:350} ERROR - Failed to import: /opt/airflow/dags/twitter_love_dag.py
Traceback (most recent call last):
  File "/home/airflow/.local/lib/python3.10/site-packages/airflow/models/dagbag.py", line 346, in parse
    loader.exec_module(new_module)
  File "<frozen importlib._bootstrap_external>", line 883, in exec_module
  File "<frozen importlib._bootstrap>", line 241, in _call_with_frames_removed
  File "/opt/airflow/dags/twitter_love_dag.py", line 15, in <module>
    with open(CREDENTIALS_PATH) as f:
FileNotFoundError: [Errno 2] No such file or directory: '/opt/airflow/data/twitter_api.json'
[2025-08-11T11:43:58.928+0000] {processor.py:842} WARNING - No viable dags retrieved from /opt/airflow/dags/twitter_love_dag.py
[2025-08-11T11:43:58.946+0000] {processor.py:183} INFO - Processing /opt/airflow/dags/twitter_love_dag.py took 0.551 seconds
[2025-08-11T11:44:29.215+0000] {processor.py:161} INFO - Started process (PID=161) to work on /opt/airflow/dags/twitter_love_dag.py
[2025-08-11T11:44:29.217+0000] {processor.py:830} INFO - Processing file /opt/airflow/dags/twitter_love_dag.py for tasks to queue
[2025-08-11T11:44:29.220+0000] {logging_mixin.py:188} INFO - [2025-08-11T11:44:29.220+0000] {dagbag.py:540} INFO - Filling up the DagBag from /opt/airflow/dags/twitter_love_dag.py
[2025-08-11T11:44:29.667+0000] {logging_mixin.py:188} INFO - [2025-08-11T11:44:29.661+0000] {dagbag.py:350} ERROR - Failed to import: /opt/airflow/dags/twitter_love_dag.py
Traceback (most recent call last):
  File "/home/airflow/.local/lib/python3.10/site-packages/airflow/models/dagbag.py", line 346, in parse
    loader.exec_module(new_module)
  File "<frozen importlib._bootstrap_external>", line 883, in exec_module
  File "<frozen importlib._bootstrap>", line 241, in _call_with_frames_removed
  File "/opt/airflow/dags/twitter_love_dag.py", line 15, in <module>
    with open(CREDENTIALS_PATH) as f:
FileNotFoundError: [Errno 2] No such file or directory: '/opt/airflow/data/twitter_api.json'
[2025-08-11T11:44:29.668+0000] {processor.py:842} WARNING - No viable dags retrieved from /opt/airflow/dags/twitter_love_dag.py
[2025-08-11T11:44:29.684+0000] {processor.py:183} INFO - Processing /opt/airflow/dags/twitter_love_dag.py took 0.475 seconds
[2025-08-11T11:44:59.833+0000] {processor.py:161} INFO - Started process (PID=167) to work on /opt/airflow/dags/twitter_love_dag.py
[2025-08-11T11:44:59.838+0000] {processor.py:830} INFO - Processing file /opt/airflow/dags/twitter_love_dag.py for tasks to queue
[2025-08-11T11:44:59.848+0000] {logging_mixin.py:188} INFO - [2025-08-11T11:44:59.847+0000] {dagbag.py:540} INFO - Filling up the DagBag from /opt/airflow/dags/twitter_love_dag.py
[2025-08-11T11:45:00.289+0000] {logging_mixin.py:188} INFO - [2025-08-11T11:45:00.286+0000] {dagbag.py:350} ERROR - Failed to import: /opt/airflow/dags/twitter_love_dag.py
Traceback (most recent call last):
  File "/home/airflow/.local/lib/python3.10/site-packages/airflow/models/dagbag.py", line 346, in parse
    loader.exec_module(new_module)
  File "<frozen importlib._bootstrap_external>", line 883, in exec_module
  File "<frozen importlib._bootstrap>", line 241, in _call_with_frames_removed
  File "/opt/airflow/dags/twitter_love_dag.py", line 15, in <module>
    with open(CREDENTIALS_PATH) as f:
FileNotFoundError: [Errno 2] No such file or directory: '/opt/airflow/data/twitter_api.json'
[2025-08-11T11:45:00.291+0000] {processor.py:842} WARNING - No viable dags retrieved from /opt/airflow/dags/twitter_love_dag.py
[2025-08-11T11:45:00.319+0000] {processor.py:183} INFO - Processing /opt/airflow/dags/twitter_love_dag.py took 0.496 seconds
[2025-08-11T11:45:30.846+0000] {processor.py:161} INFO - Started process (PID=173) to work on /opt/airflow/dags/twitter_love_dag.py
[2025-08-11T11:45:30.847+0000] {processor.py:830} INFO - Processing file /opt/airflow/dags/twitter_love_dag.py for tasks to queue
[2025-08-11T11:45:30.849+0000] {logging_mixin.py:188} INFO - [2025-08-11T11:45:30.849+0000] {dagbag.py:540} INFO - Filling up the DagBag from /opt/airflow/dags/twitter_love_dag.py
[2025-08-11T11:45:31.321+0000] {logging_mixin.py:188} INFO - [2025-08-11T11:45:31.314+0000] {dagbag.py:350} ERROR - Failed to import: /opt/airflow/dags/twitter_love_dag.py
Traceback (most recent call last):
  File "/home/airflow/.local/lib/python3.10/site-packages/airflow/models/dagbag.py", line 346, in parse
    loader.exec_module(new_module)
  File "<frozen importlib._bootstrap_external>", line 883, in exec_module
  File "<frozen importlib._bootstrap>", line 241, in _call_with_frames_removed
  File "/opt/airflow/dags/twitter_love_dag.py", line 15, in <module>
    with open(CREDENTIALS_PATH) as f:
FileNotFoundError: [Errno 2] No such file or directory: '/opt/airflow/data/twitter_api.json'
[2025-08-11T11:45:31.324+0000] {processor.py:842} WARNING - No viable dags retrieved from /opt/airflow/dags/twitter_love_dag.py
[2025-08-11T11:45:31.342+0000] {processor.py:183} INFO - Processing /opt/airflow/dags/twitter_love_dag.py took 0.503 seconds
[2025-08-11T11:46:02.064+0000] {processor.py:161} INFO - Started process (PID=179) to work on /opt/airflow/dags/twitter_love_dag.py
[2025-08-11T11:46:02.065+0000] {processor.py:830} INFO - Processing file /opt/airflow/dags/twitter_love_dag.py for tasks to queue
[2025-08-11T11:46:02.067+0000] {logging_mixin.py:188} INFO - [2025-08-11T11:46:02.067+0000] {dagbag.py:540} INFO - Filling up the DagBag from /opt/airflow/dags/twitter_love_dag.py
[2025-08-11T11:46:02.487+0000] {logging_mixin.py:188} INFO - [2025-08-11T11:46:02.482+0000] {dagbag.py:350} ERROR - Failed to import: /opt/airflow/dags/twitter_love_dag.py
Traceback (most recent call last):
  File "/home/airflow/.local/lib/python3.10/site-packages/airflow/models/dagbag.py", line 346, in parse
    loader.exec_module(new_module)
  File "<frozen importlib._bootstrap_external>", line 883, in exec_module
  File "<frozen importlib._bootstrap>", line 241, in _call_with_frames_removed
  File "/opt/airflow/dags/twitter_love_dag.py", line 15, in <module>
    with open(CREDENTIALS_PATH) as f:
FileNotFoundError: [Errno 2] No such file or directory: '/opt/airflow/data/twitter_api.json'
[2025-08-11T11:46:02.488+0000] {processor.py:842} WARNING - No viable dags retrieved from /opt/airflow/dags/twitter_love_dag.py
[2025-08-11T11:46:02.503+0000] {processor.py:183} INFO - Processing /opt/airflow/dags/twitter_love_dag.py took 0.447 seconds
[2025-08-11T11:46:32.927+0000] {processor.py:161} INFO - Started process (PID=185) to work on /opt/airflow/dags/twitter_love_dag.py
[2025-08-11T11:46:32.929+0000] {processor.py:830} INFO - Processing file /opt/airflow/dags/twitter_love_dag.py for tasks to queue
[2025-08-11T11:46:32.933+0000] {logging_mixin.py:188} INFO - [2025-08-11T11:46:32.933+0000] {dagbag.py:540} INFO - Filling up the DagBag from /opt/airflow/dags/twitter_love_dag.py
[2025-08-11T11:46:33.406+0000] {logging_mixin.py:188} INFO - [2025-08-11T11:46:33.393+0000] {dagbag.py:350} ERROR - Failed to import: /opt/airflow/dags/twitter_love_dag.py
Traceback (most recent call last):
  File "/home/airflow/.local/lib/python3.10/site-packages/airflow/models/dagbag.py", line 346, in parse
    loader.exec_module(new_module)
  File "<frozen importlib._bootstrap_external>", line 883, in exec_module
  File "<frozen importlib._bootstrap>", line 241, in _call_with_frames_removed
  File "/opt/airflow/dags/twitter_love_dag.py", line 15, in <module>
    with open(CREDENTIALS_PATH) as f:
FileNotFoundError: [Errno 2] No such file or directory: '/opt/airflow/data/twitter_api.json'
[2025-08-11T11:46:33.409+0000] {processor.py:842} WARNING - No viable dags retrieved from /opt/airflow/dags/twitter_love_dag.py
[2025-08-11T11:46:33.426+0000] {processor.py:183} INFO - Processing /opt/airflow/dags/twitter_love_dag.py took 0.507 seconds
[2025-08-11T11:47:04.415+0000] {processor.py:161} INFO - Started process (PID=191) to work on /opt/airflow/dags/twitter_love_dag.py
[2025-08-11T11:47:04.417+0000] {processor.py:830} INFO - Processing file /opt/airflow/dags/twitter_love_dag.py for tasks to queue
[2025-08-11T11:47:04.420+0000] {logging_mixin.py:188} INFO - [2025-08-11T11:47:04.419+0000] {dagbag.py:540} INFO - Filling up the DagBag from /opt/airflow/dags/twitter_love_dag.py
[2025-08-11T11:47:04.928+0000] {logging_mixin.py:188} INFO - [2025-08-11T11:47:04.920+0000] {dagbag.py:350} ERROR - Failed to import: /opt/airflow/dags/twitter_love_dag.py
Traceback (most recent call last):
  File "/home/airflow/.local/lib/python3.10/site-packages/airflow/models/dagbag.py", line 346, in parse
    loader.exec_module(new_module)
  File "<frozen importlib._bootstrap_external>", line 883, in exec_module
  File "<frozen importlib._bootstrap>", line 241, in _call_with_frames_removed
  File "/opt/airflow/dags/twitter_love_dag.py", line 15, in <module>
    with open(CREDENTIALS_PATH) as f:
FileNotFoundError: [Errno 2] No such file or directory: '/opt/airflow/data/twitter_api.json'
[2025-08-11T11:47:04.932+0000] {processor.py:842} WARNING - No viable dags retrieved from /opt/airflow/dags/twitter_love_dag.py
[2025-08-11T11:47:04.958+0000] {processor.py:183} INFO - Processing /opt/airflow/dags/twitter_love_dag.py took 0.549 seconds
[2025-08-11T11:47:35.173+0000] {processor.py:161} INFO - Started process (PID=197) to work on /opt/airflow/dags/twitter_love_dag.py
[2025-08-11T11:47:35.174+0000] {processor.py:830} INFO - Processing file /opt/airflow/dags/twitter_love_dag.py for tasks to queue
[2025-08-11T11:47:35.175+0000] {logging_mixin.py:188} INFO - [2025-08-11T11:47:35.175+0000] {dagbag.py:540} INFO - Filling up the DagBag from /opt/airflow/dags/twitter_love_dag.py
[2025-08-11T11:47:35.689+0000] {logging_mixin.py:188} INFO - [2025-08-11T11:47:35.679+0000] {dagbag.py:350} ERROR - Failed to import: /opt/airflow/dags/twitter_love_dag.py
Traceback (most recent call last):
  File "/home/airflow/.local/lib/python3.10/site-packages/airflow/models/dagbag.py", line 346, in parse
    loader.exec_module(new_module)
  File "<frozen importlib._bootstrap_external>", line 883, in exec_module
  File "<frozen importlib._bootstrap>", line 241, in _call_with_frames_removed
  File "/opt/airflow/dags/twitter_love_dag.py", line 15, in <module>
    with open(CREDENTIALS_PATH) as f:
FileNotFoundError: [Errno 2] No such file or directory: '/opt/airflow/data/twitter_api.json'
[2025-08-11T11:47:35.691+0000] {processor.py:842} WARNING - No viable dags retrieved from /opt/airflow/dags/twitter_love_dag.py
[2025-08-11T11:47:35.707+0000] {processor.py:183} INFO - Processing /opt/airflow/dags/twitter_love_dag.py took 0.539 seconds
[2025-08-11T11:48:06.508+0000] {processor.py:161} INFO - Started process (PID=203) to work on /opt/airflow/dags/twitter_love_dag.py
[2025-08-11T11:48:06.510+0000] {processor.py:830} INFO - Processing file /opt/airflow/dags/twitter_love_dag.py for tasks to queue
[2025-08-11T11:48:06.513+0000] {logging_mixin.py:188} INFO - [2025-08-11T11:48:06.513+0000] {dagbag.py:540} INFO - Filling up the DagBag from /opt/airflow/dags/twitter_love_dag.py
[2025-08-11T11:48:06.924+0000] {logging_mixin.py:188} INFO - [2025-08-11T11:48:06.919+0000] {dagbag.py:350} ERROR - Failed to import: /opt/airflow/dags/twitter_love_dag.py
Traceback (most recent call last):
  File "/home/airflow/.local/lib/python3.10/site-packages/airflow/models/dagbag.py", line 346, in parse
    loader.exec_module(new_module)
  File "<frozen importlib._bootstrap_external>", line 883, in exec_module
  File "<frozen importlib._bootstrap>", line 241, in _call_with_frames_removed
  File "/opt/airflow/dags/twitter_love_dag.py", line 15, in <module>
    with open(CREDENTIALS_PATH) as f:
FileNotFoundError: [Errno 2] No such file or directory: '/opt/airflow/data/twitter_api.json'
[2025-08-11T11:48:06.925+0000] {processor.py:842} WARNING - No viable dags retrieved from /opt/airflow/dags/twitter_love_dag.py
[2025-08-11T11:48:06.939+0000] {processor.py:183} INFO - Processing /opt/airflow/dags/twitter_love_dag.py took 0.439 seconds
[2025-08-11T11:48:37.870+0000] {processor.py:161} INFO - Started process (PID=209) to work on /opt/airflow/dags/twitter_love_dag.py
[2025-08-11T11:48:37.871+0000] {processor.py:830} INFO - Processing file /opt/airflow/dags/twitter_love_dag.py for tasks to queue
[2025-08-11T11:48:37.874+0000] {logging_mixin.py:188} INFO - [2025-08-11T11:48:37.874+0000] {dagbag.py:540} INFO - Filling up the DagBag from /opt/airflow/dags/twitter_love_dag.py
[2025-08-11T11:48:38.537+0000] {logging_mixin.py:188} INFO - [2025-08-11T11:48:38.530+0000] {dagbag.py:350} ERROR - Failed to import: /opt/airflow/dags/twitter_love_dag.py
Traceback (most recent call last):
  File "/home/airflow/.local/lib/python3.10/site-packages/airflow/models/dagbag.py", line 346, in parse
    loader.exec_module(new_module)
  File "<frozen importlib._bootstrap_external>", line 883, in exec_module
  File "<frozen importlib._bootstrap>", line 241, in _call_with_frames_removed
  File "/opt/airflow/dags/twitter_love_dag.py", line 15, in <module>
    with open(CREDENTIALS_PATH) as f:
FileNotFoundError: [Errno 2] No such file or directory: '/opt/airflow/data/twitter_api.json'
[2025-08-11T11:48:38.539+0000] {processor.py:842} WARNING - No viable dags retrieved from /opt/airflow/dags/twitter_love_dag.py
[2025-08-11T11:48:38.557+0000] {processor.py:183} INFO - Processing /opt/airflow/dags/twitter_love_dag.py took 0.696 seconds
[2025-08-11T11:49:08.608+0000] {processor.py:161} INFO - Started process (PID=215) to work on /opt/airflow/dags/twitter_love_dag.py
[2025-08-11T11:49:08.609+0000] {processor.py:830} INFO - Processing file /opt/airflow/dags/twitter_love_dag.py for tasks to queue
[2025-08-11T11:49:08.611+0000] {logging_mixin.py:188} INFO - [2025-08-11T11:49:08.611+0000] {dagbag.py:540} INFO - Filling up the DagBag from /opt/airflow/dags/twitter_love_dag.py
[2025-08-11T11:49:09.273+0000] {logging_mixin.py:188} INFO - [2025-08-11T11:49:09.147+0000] {dagbag.py:350} ERROR - Failed to import: /opt/airflow/dags/twitter_love_dag.py
Traceback (most recent call last):
  File "/home/airflow/.local/lib/python3.10/site-packages/airflow/models/dagbag.py", line 346, in parse
    loader.exec_module(new_module)
  File "<frozen importlib._bootstrap_external>", line 883, in exec_module
  File "<frozen importlib._bootstrap>", line 241, in _call_with_frames_removed
  File "/opt/airflow/dags/twitter_love_dag.py", line 15, in <module>
    with open(CREDENTIALS_PATH) as f:
FileNotFoundError: [Errno 2] No such file or directory: '/opt/airflow/data/twitter_api.json'
[2025-08-11T11:49:09.277+0000] {processor.py:842} WARNING - No viable dags retrieved from /opt/airflow/dags/twitter_love_dag.py
[2025-08-11T11:49:09.301+0000] {processor.py:183} INFO - Processing /opt/airflow/dags/twitter_love_dag.py took 0.701 seconds
[2025-08-11T11:49:39.654+0000] {processor.py:161} INFO - Started process (PID=221) to work on /opt/airflow/dags/twitter_love_dag.py
[2025-08-11T11:49:39.655+0000] {processor.py:830} INFO - Processing file /opt/airflow/dags/twitter_love_dag.py for tasks to queue
[2025-08-11T11:49:39.657+0000] {logging_mixin.py:188} INFO - [2025-08-11T11:49:39.657+0000] {dagbag.py:540} INFO - Filling up the DagBag from /opt/airflow/dags/twitter_love_dag.py
[2025-08-11T11:49:40.185+0000] {logging_mixin.py:188} INFO - [2025-08-11T11:49:40.175+0000] {dagbag.py:350} ERROR - Failed to import: /opt/airflow/dags/twitter_love_dag.py
Traceback (most recent call last):
  File "/home/airflow/.local/lib/python3.10/site-packages/airflow/models/dagbag.py", line 346, in parse
    loader.exec_module(new_module)
  File "<frozen importlib._bootstrap_external>", line 883, in exec_module
  File "<frozen importlib._bootstrap>", line 241, in _call_with_frames_removed
  File "/opt/airflow/dags/twitter_love_dag.py", line 15, in <module>
    with open(CREDENTIALS_PATH) as f:
FileNotFoundError: [Errno 2] No such file or directory: '/opt/airflow/data/twitter_api.json'
[2025-08-11T11:49:40.187+0000] {processor.py:842} WARNING - No viable dags retrieved from /opt/airflow/dags/twitter_love_dag.py
[2025-08-11T11:49:40.213+0000] {processor.py:183} INFO - Processing /opt/airflow/dags/twitter_love_dag.py took 0.566 seconds
[2025-08-11T11:50:10.989+0000] {processor.py:161} INFO - Started process (PID=227) to work on /opt/airflow/dags/twitter_love_dag.py
[2025-08-11T11:50:10.990+0000] {processor.py:830} INFO - Processing file /opt/airflow/dags/twitter_love_dag.py for tasks to queue
[2025-08-11T11:50:10.993+0000] {logging_mixin.py:188} INFO - [2025-08-11T11:50:10.992+0000] {dagbag.py:540} INFO - Filling up the DagBag from /opt/airflow/dags/twitter_love_dag.py
[2025-08-11T11:50:11.464+0000] {logging_mixin.py:188} INFO - [2025-08-11T11:50:11.439+0000] {dagbag.py:350} ERROR - Failed to import: /opt/airflow/dags/twitter_love_dag.py
Traceback (most recent call last):
  File "/home/airflow/.local/lib/python3.10/site-packages/airflow/models/dagbag.py", line 346, in parse
    loader.exec_module(new_module)
  File "<frozen importlib._bootstrap_external>", line 883, in exec_module
  File "<frozen importlib._bootstrap>", line 241, in _call_with_frames_removed
  File "/opt/airflow/dags/twitter_love_dag.py", line 15, in <module>
    with open(CREDENTIALS_PATH) as f:
FileNotFoundError: [Errno 2] No such file or directory: '/opt/airflow/data/twitter_api.json'
[2025-08-11T11:50:11.467+0000] {processor.py:842} WARNING - No viable dags retrieved from /opt/airflow/dags/twitter_love_dag.py
[2025-08-11T11:50:11.491+0000] {processor.py:183} INFO - Processing /opt/airflow/dags/twitter_love_dag.py took 0.515 seconds
[2025-08-11T11:50:42.454+0000] {processor.py:161} INFO - Started process (PID=233) to work on /opt/airflow/dags/twitter_love_dag.py
[2025-08-11T11:50:42.455+0000] {processor.py:830} INFO - Processing file /opt/airflow/dags/twitter_love_dag.py for tasks to queue
[2025-08-11T11:50:42.457+0000] {logging_mixin.py:188} INFO - [2025-08-11T11:50:42.457+0000] {dagbag.py:540} INFO - Filling up the DagBag from /opt/airflow/dags/twitter_love_dag.py
[2025-08-11T11:50:43.004+0000] {logging_mixin.py:188} INFO - [2025-08-11T11:50:42.956+0000] {dagbag.py:350} ERROR - Failed to import: /opt/airflow/dags/twitter_love_dag.py
Traceback (most recent call last):
  File "/home/airflow/.local/lib/python3.10/site-packages/airflow/models/dagbag.py", line 346, in parse
    loader.exec_module(new_module)
  File "<frozen importlib._bootstrap_external>", line 883, in exec_module
  File "<frozen importlib._bootstrap>", line 241, in _call_with_frames_removed
  File "/opt/airflow/dags/twitter_love_dag.py", line 15, in <module>
    with open(CREDENTIALS_PATH) as f:
FileNotFoundError: [Errno 2] No such file or directory: '/opt/airflow/data/twitter_api.json'
[2025-08-11T11:50:43.012+0000] {processor.py:842} WARNING - No viable dags retrieved from /opt/airflow/dags/twitter_love_dag.py
[2025-08-11T11:50:43.052+0000] {processor.py:183} INFO - Processing /opt/airflow/dags/twitter_love_dag.py took 0.604 seconds
[2025-08-11T11:51:13.125+0000] {processor.py:161} INFO - Started process (PID=239) to work on /opt/airflow/dags/twitter_love_dag.py
[2025-08-11T11:51:13.126+0000] {processor.py:830} INFO - Processing file /opt/airflow/dags/twitter_love_dag.py for tasks to queue
[2025-08-11T11:51:13.128+0000] {logging_mixin.py:188} INFO - [2025-08-11T11:51:13.128+0000] {dagbag.py:540} INFO - Filling up the DagBag from /opt/airflow/dags/twitter_love_dag.py
[2025-08-11T11:51:13.530+0000] {logging_mixin.py:188} INFO - [2025-08-11T11:51:13.496+0000] {dagbag.py:350} ERROR - Failed to import: /opt/airflow/dags/twitter_love_dag.py
Traceback (most recent call last):
  File "/home/airflow/.local/lib/python3.10/site-packages/airflow/models/dagbag.py", line 346, in parse
    loader.exec_module(new_module)
  File "<frozen importlib._bootstrap_external>", line 883, in exec_module
  File "<frozen importlib._bootstrap>", line 241, in _call_with_frames_removed
  File "/opt/airflow/dags/twitter_love_dag.py", line 15, in <module>
    with open(CREDENTIALS_PATH) as f:
FileNotFoundError: [Errno 2] No such file or directory: '/opt/airflow/data/twitter_api.json'
[2025-08-11T11:51:13.533+0000] {processor.py:842} WARNING - No viable dags retrieved from /opt/airflow/dags/twitter_love_dag.py
[2025-08-11T11:51:13.556+0000] {processor.py:183} INFO - Processing /opt/airflow/dags/twitter_love_dag.py took 0.436 seconds
[2025-08-11T11:51:44.912+0000] {processor.py:161} INFO - Started process (PID=245) to work on /opt/airflow/dags/twitter_love_dag.py
[2025-08-11T11:51:44.913+0000] {processor.py:830} INFO - Processing file /opt/airflow/dags/twitter_love_dag.py for tasks to queue
[2025-08-11T11:51:44.915+0000] {logging_mixin.py:188} INFO - [2025-08-11T11:51:44.915+0000] {dagbag.py:540} INFO - Filling up the DagBag from /opt/airflow/dags/twitter_love_dag.py
[2025-08-11T11:51:45.410+0000] {logging_mixin.py:188} INFO - [2025-08-11T11:51:45.396+0000] {dagbag.py:350} ERROR - Failed to import: /opt/airflow/dags/twitter_love_dag.py
Traceback (most recent call last):
  File "/home/airflow/.local/lib/python3.10/site-packages/airflow/models/dagbag.py", line 346, in parse
    loader.exec_module(new_module)
  File "<frozen importlib._bootstrap_external>", line 883, in exec_module
  File "<frozen importlib._bootstrap>", line 241, in _call_with_frames_removed
  File "/opt/airflow/dags/twitter_love_dag.py", line 15, in <module>
    with open(CREDENTIALS_PATH) as f:
FileNotFoundError: [Errno 2] No such file or directory: '/opt/airflow/data/twitter_api.json'
[2025-08-11T11:51:45.425+0000] {processor.py:842} WARNING - No viable dags retrieved from /opt/airflow/dags/twitter_love_dag.py
[2025-08-11T11:51:45.470+0000] {processor.py:183} INFO - Processing /opt/airflow/dags/twitter_love_dag.py took 0.566 seconds
[2025-08-11T11:52:16.010+0000] {processor.py:161} INFO - Started process (PID=251) to work on /opt/airflow/dags/twitter_love_dag.py
[2025-08-11T11:52:16.012+0000] {processor.py:830} INFO - Processing file /opt/airflow/dags/twitter_love_dag.py for tasks to queue
[2025-08-11T11:52:16.013+0000] {logging_mixin.py:188} INFO - [2025-08-11T11:52:16.013+0000] {dagbag.py:540} INFO - Filling up the DagBag from /opt/airflow/dags/twitter_love_dag.py
[2025-08-11T11:52:16.469+0000] {logging_mixin.py:188} INFO - [2025-08-11T11:52:16.461+0000] {dagbag.py:350} ERROR - Failed to import: /opt/airflow/dags/twitter_love_dag.py
Traceback (most recent call last):
  File "/home/airflow/.local/lib/python3.10/site-packages/airflow/models/dagbag.py", line 346, in parse
    loader.exec_module(new_module)
  File "<frozen importlib._bootstrap_external>", line 883, in exec_module
  File "<frozen importlib._bootstrap>", line 241, in _call_with_frames_removed
  File "/opt/airflow/dags/twitter_love_dag.py", line 15, in <module>
    with open(CREDENTIALS_PATH) as f:
FileNotFoundError: [Errno 2] No such file or directory: '/opt/airflow/data/twitter_api.json'
[2025-08-11T11:52:16.471+0000] {processor.py:842} WARNING - No viable dags retrieved from /opt/airflow/dags/twitter_love_dag.py
[2025-08-11T11:52:16.486+0000] {processor.py:183} INFO - Processing /opt/airflow/dags/twitter_love_dag.py took 0.481 seconds
[2025-08-11T11:52:47.212+0000] {processor.py:161} INFO - Started process (PID=258) to work on /opt/airflow/dags/twitter_love_dag.py
[2025-08-11T11:52:47.213+0000] {processor.py:830} INFO - Processing file /opt/airflow/dags/twitter_love_dag.py for tasks to queue
[2025-08-11T11:52:47.215+0000] {logging_mixin.py:188} INFO - [2025-08-11T11:52:47.215+0000] {dagbag.py:540} INFO - Filling up the DagBag from /opt/airflow/dags/twitter_love_dag.py
[2025-08-11T11:52:47.695+0000] {logging_mixin.py:188} INFO - [2025-08-11T11:52:47.684+0000] {dagbag.py:350} ERROR - Failed to import: /opt/airflow/dags/twitter_love_dag.py
Traceback (most recent call last):
  File "/home/airflow/.local/lib/python3.10/site-packages/airflow/models/dagbag.py", line 346, in parse
    loader.exec_module(new_module)
  File "<frozen importlib._bootstrap_external>", line 883, in exec_module
  File "<frozen importlib._bootstrap>", line 241, in _call_with_frames_removed
  File "/opt/airflow/dags/twitter_love_dag.py", line 15, in <module>
    with open(CREDENTIALS_PATH) as f:
FileNotFoundError: [Errno 2] No such file or directory: '/opt/airflow/data/twitter_api.json'
[2025-08-11T11:52:47.697+0000] {processor.py:842} WARNING - No viable dags retrieved from /opt/airflow/dags/twitter_love_dag.py
[2025-08-11T11:52:47.717+0000] {processor.py:183} INFO - Processing /opt/airflow/dags/twitter_love_dag.py took 0.511 seconds
[2025-08-11T11:53:17.949+0000] {processor.py:161} INFO - Started process (PID=264) to work on /opt/airflow/dags/twitter_love_dag.py
[2025-08-11T11:53:17.949+0000] {processor.py:830} INFO - Processing file /opt/airflow/dags/twitter_love_dag.py for tasks to queue
[2025-08-11T11:53:17.951+0000] {logging_mixin.py:188} INFO - [2025-08-11T11:53:17.951+0000] {dagbag.py:540} INFO - Filling up the DagBag from /opt/airflow/dags/twitter_love_dag.py
[2025-08-11T11:53:18.522+0000] {logging_mixin.py:188} INFO - [2025-08-11T11:53:18.418+0000] {dagbag.py:350} ERROR - Failed to import: /opt/airflow/dags/twitter_love_dag.py
Traceback (most recent call last):
  File "/home/airflow/.local/lib/python3.10/site-packages/airflow/models/dagbag.py", line 346, in parse
    loader.exec_module(new_module)
  File "<frozen importlib._bootstrap_external>", line 883, in exec_module
  File "<frozen importlib._bootstrap>", line 241, in _call_with_frames_removed
  File "/opt/airflow/dags/twitter_love_dag.py", line 15, in <module>
    with open(CREDENTIALS_PATH) as f:
FileNotFoundError: [Errno 2] No such file or directory: '/opt/airflow/data/twitter_api.json'
[2025-08-11T11:53:18.525+0000] {processor.py:842} WARNING - No viable dags retrieved from /opt/airflow/dags/twitter_love_dag.py
[2025-08-11T11:53:18.546+0000] {processor.py:183} INFO - Processing /opt/airflow/dags/twitter_love_dag.py took 0.602 seconds
[2025-08-11T11:53:49.149+0000] {processor.py:161} INFO - Started process (PID=270) to work on /opt/airflow/dags/twitter_love_dag.py
[2025-08-11T11:53:49.151+0000] {processor.py:830} INFO - Processing file /opt/airflow/dags/twitter_love_dag.py for tasks to queue
[2025-08-11T11:53:49.153+0000] {logging_mixin.py:188} INFO - [2025-08-11T11:53:49.153+0000] {dagbag.py:540} INFO - Filling up the DagBag from /opt/airflow/dags/twitter_love_dag.py
[2025-08-11T11:53:49.614+0000] {logging_mixin.py:188} INFO - [2025-08-11T11:53:49.557+0000] {dagbag.py:350} ERROR - Failed to import: /opt/airflow/dags/twitter_love_dag.py
Traceback (most recent call last):
  File "/home/airflow/.local/lib/python3.10/site-packages/airflow/models/dagbag.py", line 346, in parse
    loader.exec_module(new_module)
  File "<frozen importlib._bootstrap_external>", line 883, in exec_module
  File "<frozen importlib._bootstrap>", line 241, in _call_with_frames_removed
  File "/opt/airflow/dags/twitter_love_dag.py", line 15, in <module>
    with open(CREDENTIALS_PATH) as f:
FileNotFoundError: [Errno 2] No such file or directory: '/opt/airflow/data/twitter_api.json'
[2025-08-11T11:53:49.621+0000] {processor.py:842} WARNING - No viable dags retrieved from /opt/airflow/dags/twitter_love_dag.py
[2025-08-11T11:53:49.650+0000] {processor.py:183} INFO - Processing /opt/airflow/dags/twitter_love_dag.py took 0.507 seconds
